<?xml version='1.0'?>
<robot name="tracked_robot">
  <link name="base_link" />
  <link name="Chassis">
    <inertial>
      <origin xyz="0.08016056471355223 0.09137425589873138 0.04160371992676176" rpy="0.0 0.0 0.0" />
      <mass value="1.4907690350907317" />
      <inertia ixx="0.00601805889102517" iyy="0.011696228691038965" izz="0.015388922827137485" ixy="2.7577451823444063e-05" iyz="6.282850546029949e-06" ixz="-0.0002627279587458808" />
    </inertial>
    <visual name="Chassis_visual">
      <origin xyz="0.0 0.0 0.0" rpy="0.0 0.0 0.0" />
      <geometry>
        <mesh filename="package://robot_description/meshes/Chassis.stl" scale="0.001 0.001 0.001" />
      </geometry>
    </visual>
  </link>
  <link name="Mega-wsheeld-v5-1">
    <inertial>
      <origin xyz="0.02418645169962702 0.0395070930422259 -0.00411905463171534" rpy="0.0 1.3877787807814457e-17 -1.5407439555097887e-33" />
      <mass value="0.11143362473176022" />
      <inertia ixx="9.047827396914211e-05" iyy="2.9224349716257692e-05" izz="0.0001094102599503685" ixy="1.1926726529571194e-06" iyz="-7.481815984518112e-06" ixz="-1.8679875245636037e-06" />
    </inertial>
    <visual name="Mega-wsheeld-v5-1_visual">
      <origin xyz="0.03137191759236502 0.013716749643378474 -0.07938573051964896" rpy="-3.046067226547428 -0.09552542704236638 -9.670704939521283e-16" />
      <geometry>
        <mesh filename="package://robot_description/meshes/Mega-wsheeld-v5-1.stl" scale="0.001 0.001 0.001" />
      </geometry>
    </visual>
  </link>
  <link name="ABX00102-Dist-sensor">
    <inertial>
      <origin xyz="-2.7902965804571524e-09 -0.0008029976609260814 -2.941022425595463e-14" rpy="-1.8491283979221107e-92 -0.0 0.0" />
      <mass value="0.0016856916739247086" />
      <inertia ixx="2.2299455179065354e-07" iyy="3.099020216361134e-07" izz="8.763210384783517e-08" ixy="-3.3881317890172036e-21" iyz="-1.652105600867684e-35" ixz="3.970466940254255e-23" />
    </inertial>
    <visual name="ABX00102-Dist-sensor_visual">
      <origin xyz="-0.01268000279029657 3.019073879784173e-09 0.020499999999975982" rpy="1.5707963267948963 1.5707963267948963 0" />
      <geometry>
        <mesh filename="package://robot_description/meshes/ABX00102-Dist-sensor.stl" scale="0.001 0.001 0.001" />
      </geometry>
    </visual>
  </link>
  <link name="LD06_LiDAR-1">
    <inertial>
      <origin xyz="-0.014204457017142277 -0.014100084752629912 0.015291217178275432" rpy="0.0 -0.0 2.4308653429145085e-63" />
      <mass value="0.04311038533159423" />
      <inertia ixx="8.243348670481602e-06" iyy="8.173008631343027e-06" izz="8.943004642017862e-06" ixy="8.999748514436816e-08" iyz="6.855376574570193e-11" ixz="-5.2126762896045434e-08" />
    </inertial>
    <visual name="LD06_LiDAR-1_visual">
      <origin xyz="-0.014100000000001334 -0.014099996205906127 -1.4979567808381944e-10" rpy="1.570796326794897 3.0981004217896383e-16 -3.1415926535897927" />
      <geometry>
        <mesh filename="package://robot_description/meshes/LD06_LiDAR-1.stl" scale="0.001 0.001 0.001" />
      </geometry>
    </visual>
  </link>
  <link name="rps-kamera-v2-2">
    <inertial>
      <origin xyz="-0.008666789812617122 -0.007142473449893689 0.01049999776378952" rpy="-2.4308653429145085e-63 -0.0 0.0" />
      <mass value="0.003595639137613823" />
      <inertia ixx="2.1027707248316132e-07" iyy="1.9649321447376828e-07" izz="2.438302533578219e-07" ixy="3.8828166112959733e-08" iyz="5.2995970380071046e-14" ixz="-4.1364707892450135e-14" />
    </inertial>
    <visual name="rps-kamera-v2-2_visual">
      <origin xyz="-0.010000002131695638 -0.0010000037940929296 0.010499999999999827" rpy="1.5707963267948972 1.570796326794896 0" />
      <geometry>
        <mesh filename="package://robot_description/meshes/rps-kamera-v2-2.stl" scale="0.001 0.001 0.001" />
      </geometry>
    </visual>
  </link>
  <link name="BN0085">
    <inertial>
      <origin xyz="-0.010159999974981949 0.008889996232938983 -0.0008249978683043757" rpy="0.0 -0.0 -2.4308653429145085e-63" />
      <mass value="0.000971518679989001" />
      <inertia ixx="4.057309916859854e-08" iyy="4.983322302554467e-08" izz="8.99654955931008e-08" ixy="-1.6676364390698638e-16" iyz="-1.6940658945086007e-21" ixz="2.771990443871009e-23" />
    </inertial>
    <visual name="BN0085_visual">
      <origin xyz="-0.010159999955668826 0.008889996205907079 2.1316956200223557e-09" rpy="-3.1415926535897927 -6.261112660079148e-16 3.1415926535897922" />
      <geometry>
        <mesh filename="package://robot_description/meshes/BN0085.stl" scale="0.001 0.001 0.001" />
      </geometry>
    </visual>
  </link>
  <link name="Xstepper">
    <inertial>
      <origin xyz="-0.018356853782212242 -5.932403723818425e-10 3.0786789428915995e-09" rpy="0.0 1.622964831673269e-94 0.0" />
      <mass value="0.4621945983755269" />
      <inertia ixx="0.00012770754461035108" iyy="0.00011178199947141333" izz="0.00011178199942341385" ixy="-2.914335439641036e-16" iyz="5.51127808069434e-36" ixz="5.4210108624275216e-20" />
    </inertial>
    <visual name="Xstepper_visual">
      <origin xyz="-0.02650000095367514 -5.932737678904232e-10 3.078678960655168e-09" rpy="1.5707963267948972 4.4188023411456595e-16 1.5707963267948968" />
      <geometry>
        <mesh filename="package://robot_description/meshes/Xstepper.stl" scale="0.001 0.001 0.001" />
      </geometry>
    </visual>
  </link>
  <link name="ZStepper">
    <inertial>
      <origin xyz="2.776297111188154e-06 -2.353672812205332e-16 0.006854897258758346" rpy="0.0 -0.0 2.4308653429145085e-63" />
      <mass value="0.24015056879172078" />
      <inertia ixx="0.00010350735668827578" iyy="0.00010350535464925467" izz="5.981399662220286e-05" ixy="1.1159493643952899e-19" iyz="-1.1926223897340549e-18" ixz="2.9439365478611888e-08" />
    </inertial>
    <visual name="ZStepper_visual">
      <origin xyz="6.2322914685829464e-18 -2.6645352591003756e-17 -0.06830000059327372" rpy="-4.361590453884552e-16 3.52892318541568e-16 1.5707963267948974" />
      <geometry>
        <mesh filename="package://robot_description/meshes/ZStepper.stl" scale="0.001 0.001 0.001" />
      </geometry>
    </visual>
  </link>
  <link name="M2">
    <inertial>
      <origin xyz="-0.032468027597979884 0.006883493133901642 3.794099345810764e-09" rpy="0.0 -2.4308653429145085e-63 0.0" />
      <mass value="0.17887898702311664" />
      <inertia ixx="2.6564786434905667e-05" iyy="9.166018014948639e-05" izz="9.180363906081458e-05" ixy="8.233551945947674e-07" iyz="7.589415207398531e-18" ixz="-4.228388472693467e-17" />
    </inertial>
    <visual name="M2_visual">
      <origin xyz="-0.05299999999999996 0.007000002131695915 3.794092879871869e-09" rpy="1.5707963267948961 -1.5707963267948957 0" />
      <geometry>
        <mesh filename="package://robot_description/meshes/M2.stl" scale="0.001 0.001 0.001" />
      </geometry>
    </visual>
  </link>
  <link name="M1">
    <inertial>
      <origin xyz="0.03246802759798002 -0.006883493133901642 -3.794099239229354e-09" rpy="0.0 2.4308653429145085e-63 0.0" />
      <mass value="0.17887898702311664" />
      <inertia ixx="2.6564786434905667e-05" iyy="9.166018014948596e-05" izz="9.18036390608148e-05" ixy="8.233551945947132e-07" iyz="7.806255641895632e-18" ixz="-4.195862407518902e-17" />
    </inertial>
    <visual name="M1_visual">
      <origin xyz="0.053000000000000096 -0.007000002131695897 -3.794092826581163e-09" rpy="1.5707963267948961 1.5707963267948957 0" />
      <geometry>
        <mesh filename="package://robot_description/meshes/M1.stl" scale="0.001 0.001 0.001" />
      </geometry>
    </visual>
  </link>
  <link name="Servo">
    <inertial>
      <origin xyz="-2.056942047801158e-09 0.009321124854800368 0.0002527734566713169" rpy="1.8491283979221107e-92 -0.0 0.0" />
      <mass value="0.08417757927421474" />
      <inertia ixx="2.197945241578161e-05" iyy="1.4498007219943728e-05" izz="1.296656455925408e-05" ixy="4.2674197509029504e-16" iyz="4.056725934208263e-07" ixz="-1.9407896513848367e-16" />
    </inertial>
    <visual name="Servo_visual">
      <origin xyz="-2.0571901426791328e-09 0.010000003019074093 2.440492252731019e-14" rpy="3.1415926535897927 -1.5707963267948963 0" />
      <geometry>
        <mesh filename="package://robot_description/meshes/Servo.stl" scale="0.001 0.001 0.001" />
      </geometry>
    </visual>
  </link>
  <link name="Unyaktig-batteri-mockup-v1-1">
    <inertial>
      <origin xyz="-0.015442478889776687 -0.049292284283532536 6.447843287281537e-16" rpy="0.0 -4.434166053000029e-47 0.0" />
      <mass value="0.44056121916666674" />
      <inertia ixx="0.0007229683485945565" iyy="0.0002961347999370593" izz="0.0005678682111967814" ixy="8.917578945477197e-06" iyz="3.944862209597661e-19" ixz="1.9239754340942185e-18" />
    </inertial>
    <visual name="Unyaktig-batteri-mockup-v1-1_visual">
      <origin xyz="-0.037000001901623135 -0.04850000290747641 2.1225445336428105e-16" rpy="-2.0061351728790932e-16 1.5707963267948781 0" />
      <geometry>
        <mesh filename="package://robot_description/meshes/Unyaktig-batteri-mockup-v1-1.stl" scale="0.001 0.001 0.001" />
      </geometry>
    </visual>
  </link>
  <link name="FLLegs">
    <inertial>
      <origin xyz="-0.015500000000000043 -0.029401337217756566 -0.033301954111963995" rpy="0.0 4.004783512012162e-63 0.0" />
      <mass value="0.04732234424542792" />
      <inertia ixx="6.179916585151207e-05" iyy="4.921655750536732e-05" izz="4.2783879376001826e-05" ixy="2.710505431213761e-19" iyz="-2.5751601189587077e-05" ixz="-3.2526065174565133e-19" />
    </inertial>
    <visual name="FLLegs_visual">
      <origin xyz="0.0757 -0.06997812 0.041856790000000005" rpy="-1.5707963267948966 5.232240697894454e-32 4.930380657631324e-32" />
      <geometry>
        <mesh filename="package://robot_description/meshes/FLLegs.stl" scale="0.001 0.001 0.001" />
      </geometry>
    </visual>
  </link>
  <link name="BLLegs">
    <inertial>
      <origin xyz="-0.015499999999999972 -0.02941535337684379 0.03328840240329648" rpy="0.0 4.004783512012162e-63 0.0" />
      <mass value="0.04732165189912416" />
      <inertia ixx="6.179656945654659e-05" iyy="4.9192301414139564e-05" izz="4.280508754708165e-05" ixy="2.168404344971009e-19" iyz="2.575320182095629e-05" ixz="-2.710505431213761e-19" />
    </inertial>
    <visual name="BLLegs_visual">
      <origin xyz="0.0757 -0.06997442000000001 -0.00514929" rpy="-1.5707963267948966 5.232240697894454e-32 4.930380657631324e-32" />
      <geometry>
        <mesh filename="package://robot_description/meshes/BLLegs.stl" scale="0.001 0.001 0.001" />
      </geometry>
    </visual>
  </link>
  <link name="FRLegs">
    <inertial>
      <origin xyz="0.015499999999999972 0.02940133721775677 0.03330195411196426" rpy="0.0 -2.4308653429145085e-63 0.0" />
      <mass value="0.04732234424542792" />
      <inertia ixx="6.179916585151185e-05" iyy="4.921655750536667e-05" izz="4.2783879376001935e-05" ixy="-1.8973538018496328e-19" iyz="-2.5751601189586575e-05" ixz="-2.168404344971009e-19" />
    </inertial>
    <visual name="FRLegs_visual">
      <origin xyz="-0.07570000000000005 0.06997811999999996 -0.04185678999999979" rpy="1.5707963267948968 2.9549212311338295e-31 3.1415926535897922" />
      <geometry>
        <mesh filename="package://robot_description/meshes/FRLegs.stl" scale="0.001 0.001 0.001" />
      </geometry>
    </visual>
  </link>
  <link name="BRLegs">
    <inertial>
      <origin xyz="0.015499999999999936 0.029415353376844377 -0.033288402403296356" rpy="0.0 -2.4308653429145085e-63 0.0" />
      <mass value="0.04732165189912416" />
      <inertia ixx="6.179656945654667e-05" iyy="4.919230141414005e-05" izz="4.28050875470816e-05" ixy="-3.7947076036992655e-19" iyz="2.5753201820957938e-05" ixz="-3.2526065174565133e-19" />
    </inertial>
    <visual name="BRLegs_visual">
      <origin xyz="-0.0757 0.06997442 0.005149290000000164" rpy="1.5707963267948968 1.9688450996075658e-31 3.1415926535897922" />
      <geometry>
        <mesh filename="package://robot_description/meshes/BRLegs.stl" scale="0.001 0.001 0.001" />
      </geometry>
    </visual>
  </link>
  <link name="Gripper">
    <inertial>
      <origin xyz="-4.6564766532987275e-05 0.1356112937106048 -0.09306669261362928" rpy="0.0 -0.0 1.622964831673269e-94" />
      <mass value="0.5425163222161179" />
      <inertia ixx="0.004197043511042029" iyy="0.0017211098951416233" izz="0.0034122570266303803" ixy="2.8304691058903548e-06" iyz="0.0011078170695914893" ixz="1.0791671084746356e-05" />
    </inertial>
    <visual name="Gripper_visual">
      <origin xyz="2.439097535056334e-14 0.16707499698092595 -0.1548096820571901" rpy="-3.8064789415720203e-16 -2.22044604925038e-16 8.661448798436062e-16" />
      <geometry>
        <mesh filename="package://robot_description/meshes/Gripper.stl" scale="0.001 0.001 0.001" />
      </geometry>
    </visual>
  </link>
  <link name="Leadscrew-Rigg">
    <inertial>
      <origin xyz="-0.033123533434109814 -0.018247049581051354 -0.3474412574413765" rpy="0.0 -0.0 2.4308653429145085e-63" />
      <mass value="0.2552161680137732" />
      <inertia ixx="0.00039226422073400033" iyy="0.0002642459548445851" izz="0.0003672622292433098" ixy="-5.1958715055313056e-05" iyz="5.81302724336377e-05" ixz="3.300694837829948e-05" />
    </inertial>
    <visual name="Leadscrew-Rigg_visual">
      <origin xyz="-0.027999999999975118 -0.011000003078674716 -0.3600000005932737" rpy="-3.806478941571969e-16 3.6373788407255685e-16 1.5707963267948974" />
      <geometry>
        <mesh filename="package://robot_description/meshes/Leadscrew-Rigg.stl" scale="0.001 0.001 0.001" />
      </geometry>
    </visual>
  </link>
  <link name="RLeadscrew">
    <inertial>
      <origin xyz="2.482014593852e-14 3.0786746041400194e-09 -0.25012949940672613" rpy="0.0 -0.0 -2.4308653429145085e-63" />
      <mass value="0.31432199985843523" />
      <inertia ixx="0.0065571253831329425" iyy="0.006557125383132946" izz="3.929024998230654e-06" ixy="1.5178830414797056e-18" iyz="-2.6020852139652103e-18" ixz="-2.602085213965211e-18" />
    </inertial>
    <visual name="RLeadscrew_visual">
      <origin xyz="-5.437442682421079e-07 3.078674595258235e-09 -0.49999999940672624" rpy="3.1415926535897927 -3.602684371206032e-16 -1.5707963267948974" />
      <geometry>
        <mesh filename="package://robot_description/meshes/RLeadscrew.stl" scale="0.001 0.001 0.001" />
      </geometry>
    </visual>
  </link>
  <link name="LeadNutR">
    <inertial>
      <origin xyz="3.651656754755095e-13 3.0786746574307247e-09 5.932737678904232e-10" rpy="0.0 -0.0 -4.487573524130272e-47" />
      <mass value="0.03449007966719112" />
      <inertia ixx="1.9041634639065265e-06" iyy="1.9041634831149027e-06" izz="2.5499387618405263e-06" ixy="1.3552527156068792e-20" iyz="4.190992178186622e-23" ixz="2.713725373551506e-20" />
    </inertial>
    <visual name="LeadNutR_visual">
      <origin xyz="2.488231842789901e-14 3.0786747018396455e-09 5.932737678904232e-10" rpy="3.1415926535897927 -3.6373788407255665e-16 -1.5707963267948974" />
      <geometry>
        <mesh filename="package://robot_description/meshes/LeadNutR.stl" scale="0.001 0.001 0.001" />
      </geometry>
    </visual>
  </link>
  <link name="StøtteStag-1">
    <inertial>
      <origin xyz="2.5077717680233035e-14 3.0786794469328525e-09 -0.22217614029023253" rpy="0.0 -0.0 -2.4308653429145085e-63" />
      <mass value="0.06992645940152016" />
      <inertia ixx="0.0011549016478399014" iyy="0.001154901647839924" izz="2.1848557574034617e-07" ixy="4.235164736271491e-20" iyz="-7.101524229780054e-18" ixz="-4.336808689942019e-19" />
    </inertial>
    <visual name="StøtteStag-1_visual">
      <origin xyz="0.016500000476875058 -0.06509999692132513 -0.09649999749937761" rpy="3.1415926535897927 -3.376759103600807e-16 -1.5707963267948974" />
      <geometry>
        <mesh filename="package://robot_description/meshes/StøtteStag-1.stl" scale="0.001 0.001 0.001" />
      </geometry>
    </visual>
  </link>
  <link name="LLeadscrew">
    <inertial>
      <origin xyz="2.495781359357352e-14 3.078674630785372e-09 -0.2501294994067262" rpy="0.0 -0.0 -2.4308653429145085e-63" />
      <mass value="0.3143219998584353" />
      <inertia ixx="0.006557125383132981" iyy="0.006557125383132981" izz="3.929024998230654e-06" ixy="-1.5178830414797068e-18" iyz="-2.6020852139652103e-18" ixz="2.6020852139652103e-18" />
    </inertial>
    <visual name="LLeadscrew_visual">
      <origin xyz="5.437443180200674e-07 3.078674630785372e-09 -0.49999999940672624" rpy="3.737090002532901e-16 -3.6026843712060373e-16 -1.5707963267948974" />
      <geometry>
        <mesh filename="package://robot_description/meshes/LLeadscrew.stl" scale="0.001 0.001 0.001" />
      </geometry>
    </visual>
  </link>
  <link name="Stepper-Gear-9R24.00-m2.741-1">
    <inertial>
      <origin xyz="-2.818797729953193e-11 -5.833247485043103e-10 3.1097953234748844e-09" rpy="-1.5192908393215678e-64 -2.1895288505075267e-47 -2.1895288505075267e-47" />
      <mass value="0.011184599309797512" />
      <inertia ixx="1.1528587359188312e-06" iyy="9.477710389925056e-07" izz="9.477710083916819e-07" ixy="7.940738931980556e-19" iyz="1.9901337230477128e-14" ixz="-7.89884693094236e-19" />
    </inertial>
    <visual name="Stepper-Gear-9R24.00-m2.741-1_visual">
      <origin xyz="2.4901053441439557e-14 -5.932737323632864e-10 3.0786787474923474e-09" rpy="-1.570796326794896 6.106226635438364e-16 1.5707963267948968" />
      <geometry>
        <mesh filename="package://robot_description/meshes/Stepper-Gear-9R24.00-m2.741-1.stl" scale="0.001 0.001 0.001" />
      </geometry>
    </visual>
  </link>
  <link name="Gear-9R24.00-m2.741-1-1">
    <inertial>
      <origin xyz="-2.887466973855446e-11 -5.614443665535873e-10 3.0685200869129403e-09" rpy="-1.5192908393215678e-64 -2.1895288505075267e-47 -2.1895288505075267e-47" />
      <mass value="0.01091885827041561" />
      <inertia ixx="1.1506677011822132e-06" iyy="9.378174561564575e-07" izz="9.378174871989267e-07" ixy="-7.928422964324558e-19" iyz="-1.9969160894130766e-14" ixz="-7.917640474459565e-19" />
    </inertial>
    <visual name="Gear-9R24.00-m2.741-1-1_visual">
      <origin xyz="2.484470962293983e-14 -5.932737323632864e-10 3.0786789473324915e-09" rpy="3.1415926535897927 1.5707963267948957 0" />
      <geometry>
        <mesh filename="package://robot_description/meshes/Gear-9R24.00-m2.741-1-1.stl" scale="0.001 0.001 0.001" />
      </geometry>
    </visual>
  </link>
  <link name="PI5">
    <inertial>
      <origin xyz="0.04800437198436048 -0.028400767420720036 0.003308340150639797" rpy="0.0 -0.0 2.4308653429145085e-63" />
      <mass value="0.01309093635557877" />
      <inertia ixx="3.7760474127176177e-06" iyy="8.765668782811318e-06" izz="1.2088625209880473e-05" ixy="2.1973352398995335e-06" iyz="3.728303439129064e-07" ixz="-6.827585355427648e-07" />
    </inertial>
    <visual name="PI5_visual">
      <origin xyz="0.038999999999998404 -0.024499996205909584 -0.00010000213169560013" rpy="1.570796326794897 3.25136742925951e-16 -3.1415926535897927" />
      <geometry>
        <mesh filename="package://robot_description/meshes/PI5.stl" scale="0.001 0.001 0.001" />
      </geometry>
    </visual>
  </link>
  <link name="Finger-R16L30.00-m2.1651Mirror">
    <inertial>
      <origin xyz="0.007278947334412944 -0.002033110697090983 -0.0016791814166278486" rpy="0.0 -0.0 -2.503791303201941e-61" />
      <mass value="0.047559344696753665" />
      <inertia ixx="1.4215694924701729e-05" iyy="2.8868593743003286e-05" izz="2.6360063365784887e-05" ixy="5.843564636721019e-06" iyz="6.943025071175318e-07" ixz="-2.8994167820624003e-06" />
    </inertial>
    <visual name="Finger-R16L30.00-m2.1651Mirror_visual">
      <origin xyz="2.445155189434445e-14 -1.1578782377341668e-09 0.03193750277245858" rpy="-7.126220392828896e-17 3.0607540456479503e-16 2.967059728390359" />
      <geometry>
        <mesh filename="package://robot_description/meshes/Finger-R16L30.00-m2.1651Mirror.stl" scale="0.001 0.001 0.001" />
      </geometry>
    </visual>
  </link>
  <link name="Top-Rack-200.0mm-R30.00-m2.1651">
    <inertial>
      <origin xyz="0.09286034750598283 -0.002008143092818209 0.0014083250852405982" rpy="0.0 -0.0 0.0" />
      <mass value="0.02617962275433629" />
      <inertia ixx="8.65207467114085e-07" iyy="5.973778917641397e-05" izz="5.992421572194773e-05" ixy="4.838558392978567e-07" iyz="-5.7308515056685074e-08" ixz="-3.4007141145274005e-07" />
    </inertial>
    <visual name="Top-Rack-200.0mm-R30.00-m2.1651_visual">
      <origin xyz="0.1087820026544988 -0.0013749990815027503 0.008000002057190035" rpy="3.8064789415720203e-16 -3.4450928483977336e-16 3.1415926535897922" />
      <geometry>
        <mesh filename="package://robot_description/meshes/Top-Rack-200.0mm-R30.00-m2.1651.stl" scale="0.001 0.001 0.001" />
      </geometry>
    </visual>
  </link>
  <link name="Bottom-Rack-200.0mm-L30.00-m2.1651">
    <inertial>
      <origin xyz="-0.09283627698778352 0.002008826258138647 0.001533881560885546" rpy="0.0 -0.0 0.0" />
      <mass value="0.02619004416035449" />
      <inertia ixx="8.685665796026847e-07" iyy="5.9778217543458334e-05" izz="5.996201862310067e-05" ixy="4.830662767776742e-07" iyz="8.379233628862657e-08" ixz="3.199029400920244e-07" />
    </inertial>
    <visual name="Bottom-Rack-200.0mm-L30.00-m2.1651_visual">
      <origin xyz="-0.10858320791413473 0.001375001589471161 0.007999997942809797" rpy="3.8064789415720163e-16 3.4450928483977336e-16 -3.1415926535897922" />
      <geometry>
        <mesh filename="package://robot_description/meshes/Bottom-Rack-200.0mm-L30.00-m2.1651.stl" scale="0.001 0.001 0.001" />
      </geometry>
    </visual>
  </link>
  <link name="Servo-Gear-8L30.00-m2.1651">
    <inertial>
      <origin xyz="-1.132171713602581e-09 -1.8507292587344182e-10 -0.0001370544270754337" rpy="0.0 -0.0 0.0" />
      <mass value="0.002870206785412932" />
      <inertia ixx="1.1070664527709404e-07" iyy="1.1070519089534012e-07" izz="1.7437457174903352e-07" ixy="2.1511843548092998e-13" iyz="-2.002202928192559e-15" ixz="-1.1237990569455117e-15" />
    </inertial>
    <visual name="Servo-Gear-8L30.00-m2.1651_visual">
      <origin xyz="2.4392016184648925e-14 2.057190160442701e-09 -0.00021800301907408227" rpy="-3.141592653589793 3.806478941571967e-16 1.5707963267948963" />
      <geometry>
        <mesh filename="package://robot_description/meshes/Servo-Gear-8L30.00-m2.1651.stl" scale="0.001 0.001 0.001" />
      </geometry>
    </visual>
  </link>
  <link name="Finger-L-16L30.00-m2.1651">
    <inertial>
      <origin xyz="0.0068680458231481015 -0.0031140099015739865 0.0016750560862786746" rpy="0.0 -0.0 -2.503791303201941e-61" />
      <mass value="0.04765014920834861" />
      <inertia ixx="1.4526108576757377e-05" iyy="2.8583472022557916e-05" izz="2.639129886920737e-05" ixy="6.2022278631304656e-06" iyz="-1.3311426072136146e-06" ixz="2.666016491166623e-06" />
    </inertial>
    <visual name="Finger-L-16L30.00-m2.1651_visual">
      <origin xyz="2.4336088699783433e-14 -1.157878024571346e-09 0.018062502295621567" rpy="-3.1415926535897927 2.321255814241268e-16 2.617993877991493" />
      <geometry>
        <mesh filename="package://robot_description/meshes/Finger-L-16L30.00-m2.1651.stl" scale="0.001 0.001 0.001" />
      </geometry>
    </visual>
  </link>
  <link name="LTWheel">
    <inertial>
      <origin xyz="-0.015499747647323422 -2.0571897163534913e-09 -3.79407328665593e-09" rpy="0.0 4.004783512012162e-63 0.0" />
      <mass value="0.01930133239557942" />
      <inertia ixx="4.477610695690975e-06" iyy="4.013472500975497e-06" izz="4.013475199122975e-06" ixy="2.710505431213761e-20" iyz="3.0662950477322592e-12" ixz="5.149960319306146e-18" />
    </inertial>
    <visual name="LTWheel_visual">
      <origin xyz="-0.0004999988555908175 -2.0571900538612907e-09 -3.794092950926143e-09" rpy="-3.8064789415719705e-16 1.5707963267948957 0" />
      <geometry>
        <mesh filename="package://robot_description/meshes/LTWheel.stl" scale="0.001 0.001 0.001" />
      </geometry>
    </visual>
  </link>
  <link name="LDriveWheel">
    <inertial>
      <origin xyz="-0.018457269510621634 -0.00012751803922465222 -3.420239832314209e-05" rpy="0.0 3.852854428080005e-63 0.0" />
      <mass value="0.03296579662050264" />
      <inertia ixx="6.4165385788824206e-06" iyy="6.063064954487589e-06" izz="6.008971414222879e-06" ixy="2.0171403547974368e-08" iyz="1.5634898593895954e-08" ixz="5.4207224848158014e-09" />
    </inertial>
    <visual name="LDriveWheel_visual">
      <origin xyz="-0.0029999999999999628 -0.03000000213169595 -3.7940925778912064e-09" rpy="1.5707963267948963 1.5707963267948957 0" />
      <geometry>
        <mesh filename="package://robot_description/meshes/LDriveWheel.stl" scale="0.001 0.001 0.001" />
      </geometry>
    </visual>
  </link>
  <link name="RBWheel">
    <inertial>
      <origin xyz="-3.0335145018156598e-09 1.237905955520091e-09 2.1177070074429595e-07" rpy="-1.8767390147207368e-47 -0.0 0.0" />
      <mass value="0.019302617704593204" />
      <inertia ixx="4.013621669145067e-06" iyy="4.013651574184693e-06" izz="4.47770267070338e-06" ixy="4.454172778902603e-12" iyz="5.204543950172628e-18" ixz="1.6764003903904945e-20" />
    </inertial>
    <visual name="RBWheel_visual">
      <origin xyz="-3.0335147371829407e-09 1.2379256197903033e-09 0.014999999999999982" rpy="3.1415926535897922 4.407156587841879e-31 1.570796326794897" />
      <geometry>
        <mesh filename="package://robot_description/meshes/RBWheel.stl" scale="0.001 0.001 0.001" />
      </geometry>
    </visual>
  </link>
  <link name="RDriveWheel">
    <inertial>
      <origin xyz="0.018457189210134024 0.00012749317873819165 3.4238858799469086e-05" rpy="0.0 -2.582794426846665e-63 0.0" />
      <mass value="0.03296508821145091" />
      <inertia ixx="6.416414177530137e-06" iyy="6.062937296905384e-06" izz="6.008866105006237e-06" ixy="2.0141371297172474e-08" iyz="1.5669165913021442e-08" ixz="5.420977719288681e-09" />
    </inertial>
    <visual name="RDriveWheel_visual">
      <origin xyz="0.0030000000000000695 0.030000002131695905 3.794092719999753e-09" rpy="1.570796326794896 -1.5707963267948957 0" />
      <geometry>
        <mesh filename="package://robot_description/meshes/RDriveWheel.stl" scale="0.001 0.001 0.001" />
      </geometry>
    </visual>
  </link>
  <link name="LFWheel">
    <inertial>
      <origin xyz="4.755825757651877e-09 3.6086565025073014e-09 2.512082673256089e-07" rpy="0.0 -0.0 0.0" />
      <mass value="0.01930133239557942" />
      <inertia ixx="4.0134725009753885e-06" iyy="4.013475199122948e-06" izz="4.477610695690948e-06" ixy="3.066295034179732e-12" iyz="5.123228854642582e-18" ixz="6.5995878835186786e-21" />
    </inertial>
    <visual name="LFWheel_visual">
      <origin xyz="4.755825413482739e-09 3.6086368560006576e-09 0.014999999999999939" rpy="9.714451465470019e-17 4.5102810375396837e-17 -1.570796326794897" />
      <geometry>
        <mesh filename="package://robot_description/meshes/LFWheel.stl" scale="0.001 0.001 0.001" />
      </geometry>
    </visual>
  </link>
  <link name="LBWheel">
    <inertial>
      <origin xyz="-3.033514444084062e-09 -1.2379058045297598e-09 2.5120826743219025e-07" rpy="0.0 -0.0 0.0" />
      <mass value="0.01930133239557942" />
      <inertia ixx="4.01347250097528e-06" iyy="4.013475199122921e-06" izz="4.477610695690894e-06" ixy="3.0662950307916003e-12" iyz="5.150333908954719e-18" ixz="3.2114560945014592e-21" />
    </inertial>
    <visual name="LBWheel_visual">
      <origin xyz="-3.0335147882532e-09 -1.2379254687999718e-09 0.015000000000000045" rpy="9.025644272762886e-17 4.857225732735074e-17 -1.570796326794897" />
      <geometry>
        <mesh filename="package://robot_description/meshes/LBWheel.stl" scale="0.001 0.001 0.001" />
      </geometry>
    </visual>
  </link>
  <link name="RFWheel">
    <inertial>
      <origin xyz="4.755825744329201e-09 3.6086563071080493e-09 -2.117707006554781e-07" rpy="-1.8767390147207353e-47 -0.0 0.0" />
      <mass value="0.01930261770459319" />
      <inertia ixx="4.013621669145067e-06" iyy="4.013651574184693e-06" izz="4.4777026707033525e-06" ixy="-4.454172782290735e-12" iyz="5.204543950172628e-18" ixz="-9.987740325870553e-21" />
    </inertial>
    <visual name="RFWheel_visual">
      <origin xyz="4.7558254934187975e-09 3.608636642837837e-09 -0.014999999999999894" rpy="-7.297455123601044e-16 1.7347234759760804e-18 -1.570796326794897" />
      <geometry>
        <mesh filename="package://robot_description/meshes/RFWheel.stl" scale="0.001 0.001 0.001" />
      </geometry>
    </visual>
  </link>
  <link name="RTWheel">
    <inertial>
      <origin xyz="0.015499788229299122 2.0571898051713334e-09 3.794073535345888e-09" rpy="0.0 -2.4308653429145085e-63 0.0" />
      <mass value="0.01930261770459319" />
      <inertia ixx="4.477702670703325e-06" iyy="4.013621669145067e-06" izz="4.01365157418472e-06" ixy="2.710505431213761e-20" iyz="-4.454172761961944e-12" ixz="-5.2583805365546965e-18" />
    </inertial>
    <visual name="RTWheel_visual">
      <origin xyz="0.0004999999999998739 2.0571900449795067e-09 3.7940931818525315e-09" rpy="3.1415926535897927 -1.5707963267948957 0" />
      <geometry>
        <mesh filename="package://robot_description/meshes/RTWheel.stl" scale="0.001 0.001 0.001" />
      </geometry>
    </visual>
  </link>
  <link name="RTracks">
    <inertial>
      <origin xyz="0.015497001220170227 -2.1846574448984858e-05 -0.03808202683919858" rpy="0.0 -0.0 1.0078327530580147e-47" />
      <mass value="0.12017843301436808" />
      <inertia ixx="0.0015067502460037604" iyy="0.00025369476259429224" izz="0.0012710822512843872" ixy="-2.675703037241863e-11" iyz="-3.397867383094469e-07" ixz="-1.8558039522643504e-08" />
    </inertial>
    <visual name="RTracks_visual">
      <origin xyz="-0.07570670275216816 -0.018303296940042214 -0.08511507140488098" rpy="0.0009707120072640304 7.874654083292796e-05 -1.1124863196142852e-16" />
      <geometry>
        <mesh filename="package://robot_description/meshes/RTracks.stl" scale="0.001 0.001 0.001" />
      </geometry>
      <material name="RTracks_hidden_material">
        <color rgba="0 0 0 0" />
      </material>
    </visual>
    <collision name="RTracks_drive_proxy_collision">
      <origin xyz="0.0912 0.01835843 -0.0965" rpy="0 0 0" />
      <geometry>
        <box size="0.030 0.210 0.007" />
      </geometry>
    </collision>
    <visual name="RTracks_drive_proxy_visual">
      <origin xyz="0.0912 0.01835843 -0.0965" rpy="0 0 0" />
      <geometry>
        <box size="0.030 0.210 0.007" />
      </geometry>
      <material name="RTracks_proxy_material">
        <color rgba="0 0.8 0.25 0.75" />
      </material>
    </visual>
  </link>
  <link name="LTracks">
    <inertial>
      <origin xyz="-0.015502998683714067 -2.1846574449120305e-05 -0.03807958569643533" rpy="5.473822126268817e-48 -0.0 8.446604675068861e-48" />
      <mass value="0.12017843301436808" />
      <inertia ixx="0.0015067502460037606" iyy="0.0002536947625942929" izz="0.0012710822512843954" ixy="-2.675703007410278e-11" iyz="-3.3978673830822716e-07" ixz="-1.8558039522449362e-08" />
    </inertial>
    <visual name="LTracks_visual">
      <origin xyz="-0.10670670265605249 -0.01830329694004238 -0.08511263026211786" rpy="0.0009707120072640304 7.874654083273901e-05 1.121604795330732e-17" />
      <geometry>
        <mesh filename="package://robot_description/meshes/LTracks.stl" scale="0.001 0.001 0.001" />
      </geometry>
      <material name="LTracks_hidden_material">
        <color rgba="0 0 0 0" />
      </material>
    </visual>
    <collision name="LTracks_drive_proxy_collision">
      <origin xyz="0.0912 0.01835843 -0.0965" rpy="0 0 0" />
      <geometry>
        <box size="0.030 0.210 0.007" />
      </geometry>
    </collision>
    <visual name="LTracks_drive_proxy_visual">
      <origin xyz="0.0912 0.01835843 -0.0965" rpy="0 0 0" />
      <geometry>
        <box size="0.030 0.210 0.007" />
      </geometry>
      <material name="LTracks_proxy_material">
        <color rgba="0 0.25 1 0.75" />
      </material>
    </visual>
  </link>
  <link name="LeadNutL">
    <inertial>
      <origin xyz="3.65143471015017e-13 3.0786747018396455e-09 5.932736968361497e-10" rpy="-3.0814879110195774e-33 4.930380657631324e-32 -2.899415157508014e-47" />
      <mass value="0.03449007966719112" />
      <inertia ixx="1.9041634639065265e-06" iyy="1.9041634831149027e-06" izz="2.549938761840499e-06" ixy="1.3552527156068792e-20" iyz="5.654597688218619e-23" ixz="2.6946065840981603e-20" />
    </inertial>
    <visual name="LeadNutL_visual">
      <origin xyz="2.4860113967406507e-14 3.0786747462485663e-09 5.932736968361497e-10" rpy="3.141592653589793 -9.034272702235832e-17 -1.5707963267948974" />
      <geometry>
        <mesh filename="package://robot_description/meshes/LeadNutL.stl" scale="0.001 0.001 0.001" />
      </geometry>
    </visual>
  </link>
  <link name="RBWheelColision">
    <inertial>
      <origin xyz="-3.033514845984797e-09 1.2379253533367774e-09 -7.105427357601002e-17" rpy="-1.8767390147207368e-47 -0.0 0.0" />
      <mass value="0.4624031863395291" />
      <inertia ixx="0.00010693073948690995" iyy="0.00010693073948690301" izz="0.00014450099573109837" ixy="-7.560427017958604e-34" iyz="2.1986451153486987e-18" ixz="9.411917832625387e-20" />
    </inertial>
    <visual name="RBWheelColision_visual">
      <origin xyz="-0.011209100000000196 0.07165210999999978 0.09119999942779532" rpy="-4.418802341145651e-16 1.5707963267948957 0" />
      <geometry>
        <mesh filename="package://robot_description/meshes/RBWheelColision.stl" scale="0.001 0.001 0.001" />
      </geometry>
      <material name="RBWheelColision_visible_material">
        <color rgba="0.95 0.2 0.05 1" />
      </material>
    </visual>
    <collision name="RBWheelColision_collision">
      <origin xyz="-0.011209100000000196 0.07165210999999978 0.09119999942779532" rpy="-4.418802341145651e-16 1.5707963267948957 0" />
      <geometry>
        <mesh filename="package://robot_description/meshes/RBWheelColision.stl" scale="0.001 0.001 0.001" />
      </geometry>
    </collision>
  </link>
  <link name="RFWheelColision">
    <inertial>
      <origin xyz="4.755825395719171e-09 -3.608636873764226e-09 -1.2434497875801754e-16" rpy="-1.8767390147207353e-47 -0.0 0.0" />
      <mass value="0.4624031863395291" />
      <inertia ixx="0.00010693073948690908" iyy="0.00010693073948690518" izz="0.00014450099573110227" ixy="-1.0842021724855105e-19" iyz="8.976025083660951e-19" ixz="-3.395616906679496e-19" />
    </inertial>
    <visual name="RFWheelColision_visual">
      <origin xyz="-0.011209092210659959 0.07165210515343755 0.09119999942779526" rpy="-4.418802341145646e-16 1.5707963267948957 0" />
      <geometry>
        <mesh filename="package://robot_description/meshes/RFWheelColision.stl" scale="0.001 0.001 0.001" />
      </geometry>
      <material name="RFWheelColision_visible_material">
        <color rgba="0.95 0.2 0.05 1" />
      </material>
    </visual>
    <collision name="RFWheelColision_collision">
      <origin xyz="-0.011209092210659959 0.07165210515343755 0.09119999942779526" rpy="-4.418802341145646e-16 1.5707963267948957 0" />
      <geometry>
        <mesh filename="package://robot_description/meshes/RFWheelColision.stl" scale="0.001 0.001 0.001" />
      </geometry>
    </collision>
  </link>
  <link name="LBWheelColision">
    <inertial>
      <origin xyz="-3.0335149614479916e-09 -1.237925202346446e-09 0.0" rpy="0.0 -0.0 0.0" />
      <mass value="0.4624031863395291" />
      <inertia ixx="0.00010693073948691602" iyy="0.00010693073948690431" izz="0.00014450099573109923" ixy="1.0842021724855026e-19" iyz="4.639216393718915e-19" ixz="-1.4301038922294687e-20" />
    </inertial>
    <visual name="LBWheelColision_visual">
      <origin xyz="-0.011209100000000211 -0.07165210999999959 -0.09119999942779533" rpy="3.141592653589793 -1.570796326794896 0" />
      <geometry>
        <mesh filename="package://robot_description/meshes/LBWheelColision.stl" scale="0.001 0.001 0.001" />
      </geometry>
      <material name="LBWheelColision_visible_material">
        <color rgba="0.95 0.2 0.05 1" />
      </material>
    </visual>
    <collision name="LBWheelColision_collision">
      <origin xyz="-0.011209100000000211 -0.07165210999999959 -0.09119999942779533" rpy="3.141592653589793 -1.570796326794896 0" />
      <geometry>
        <mesh filename="package://robot_description/meshes/LBWheelColision.stl" scale="0.001 0.001 0.001" />
      </geometry>
    </collision>
  </link>
  <link name="RFWheelColision-1">
    <inertial>
      <origin xyz="4.755825313562667e-09 -3.6086372467991626e-09 7.105427357601002e-17" rpy="0.0 -0.0 0.0" />
      <mass value="0.4624031863395291" />
      <inertia ixx="0.00010693073948691428" iyy="0.00010693073948690084" izz="0.00014450099573110053" ixy="-8.858954843393796e-34" iyz="-8.3712096761071e-19" ixz="-6.904303731932821e-19" />
    </inertial>
    <visual name="RFWheelColision-1_visual">
      <origin xyz="-0.01120909221065994 0.07165210515343713 0.09119999942779536" rpy="1.2325951644077918e-32 1.5707963267948954 0" />
      <geometry>
        <mesh filename="package://robot_description/meshes/RFWheelColision-1.stl" scale="0.001 0.001 0.001" />
      </geometry>
      <material name="RFWheelColision-1_visible_material">
        <color rgba="0.95 0.2 0.05 1" />
      </material>
    </visual>
    <collision name="RFWheelColision-1_collision">
      <origin xyz="-0.01120909221065994 0.07165210515343713 0.09119999942779536" rpy="1.2325951644077918e-32 1.5707963267948954 0" />
      <geometry>
        <mesh filename="package://robot_description/meshes/RFWheelColision-1.stl" scale="0.001 0.001 0.001" />
      </geometry>
    </collision>
  </link>
  <joint name="Chassis_Revolute-1" type="revolute">
    <origin xyz="0.05649392620590695 0.01579999999999999 0.044996302057189935" rpy="-1.5707963267948961 3.8064789415719715e-16 -1.5707963267948974" />
    <parent link="Chassis" />
    <child link="BRLegs" />
    <axis xyz="-1.0 4.930380657631324e-32 -1.4489281932630845e-31" />
    <limit lower="0.0" upper="0.261799" effort="1000000" velocity="1000000" />
  </joint>
  <joint name="Chassis_Revolute-2" type="revolute">
    <origin xyz="0.10350000620590694 0.015799999999999956 0.04500000205718996" rpy="-1.5707963267948961 3.8064789415719715e-16 -1.5707963267948974" />
    <parent link="Chassis" />
    <child link="FRLegs" />
    <axis xyz="-1.0 4.930380657631324e-32 -1.4489281932630845e-31" />
    <limit lower="-0.261799" upper="0.0" effort="1000000" velocity="1000000" />
  </joint>
  <joint name="BRLegs_Revolute-3" type="fixed">
    <origin xyz="0.01549999999999999 0.05876532 -0.06650282" rpy="1.5707963267948974 -2.465190328815662e-31 -1.5707963267948961" />
    <parent link="BRLegs" />
    <child link="RBWheel" />
  </joint>
  <joint name="FRLegs_Revolute-4" type="fixed">
    <origin xyz="0.01549999999999999 0.05873733 0.06652989999999999" rpy="-1.5707963267948957 -2.465190328815662e-31 -1.5707963267948961" />
    <parent link="FRLegs" />
    <child link="RFWheel" />
  </joint>
  <joint name="Chassis_Revolute-5" type="fixed">
    <origin xyz="0.2199999962059069 0.015799999999999866 0.04500000205718999" rpy="-1.5707963267948961 3.8064789415719715e-16 -1.5707963267948974" />
    <parent link="Chassis" />
    <child link="RTWheel" />
  </joint>
  <joint name="Chassis_Revolute-6" type="fixed">
    <origin xyz="-0.060000003794093 0.01830000000000009 0.04525000205718989" rpy="-1.5707963267948961 3.8064789415719715e-16 -1.5707963267948974" />
    <parent link="Chassis" />
    <child link="RDriveWheel" />
  </joint>
  <joint name="Chassis_Revolute-7" type="revolute">
    <origin xyz="0.10350000620590706 0.16719999999999988 0.04500000205719001" rpy="1.570796326794897 3.8064789415719715e-16 -1.5707963267948974" />
    <parent link="Chassis" />
    <child link="FLLegs" />
    <axis xyz="1.0 4.930380657631324e-32 -1.4489281932630845e-31" />
    <limit lower="0.0" upper="0.261799" effort="1000000" velocity="1000000" />
  </joint>
  <joint name="Chassis_Revolute-8" type="revolute">
    <origin xyz="0.056493926205907076 0.16719999999999993 0.04499630205718999" rpy="1.570796326794897 3.8064789415719715e-16 -1.5707963267948974" />
    <parent link="Chassis" />
    <child link="BLLegs" />
    <axis xyz="1.0 4.930380657631324e-32 -1.4489281932630845e-31" />
    <limit lower="-0.261799" upper="0.0" effort="1000000" velocity="1000000" />
  </joint>
  <joint name="FLLegs_Revolute-9" type="fixed">
    <origin xyz="-0.01549999999999999 -0.05873733 -0.06652989999999999" rpy="1.5707963267948974 -3.8761492285297827e-31 1.570796326794897" />
    <parent link="FLLegs" />
    <child link="LFWheel" />
  </joint>
  <joint name="BLLegs_Revolute-10" type="fixed">
    <origin xyz="-0.01549999999999999 -0.05876532 0.06650282" rpy="1.5707963267948974 -3.8761492285297827e-31 1.570796326794897" />
    <parent link="BLLegs" />
    <child link="LBWheel" />
  </joint>
  <joint name="Chassis_Revolute-11" type="fixed">
    <origin xyz="-0.0600000037940929 0.16470000000000004 0.045250002057189945" rpy="1.570796326794897 3.8064789415719715e-16 -1.5707963267948974" />
    <parent link="Chassis" />
    <child link="LDriveWheel" />
  </joint>
  <joint name="Chassis_Revolute-12" type="fixed">
    <origin xyz="0.219999996205907 0.16719999999999982 0.04500000205719005" rpy="1.570796326794897 3.8064789415719715e-16 -1.5707963267948974" />
    <parent link="Chassis" />
    <child link="LTWheel" />
  </joint>
  <joint name="Chassis_Rigid-13" type="fixed">
    <origin xyz="-0.06407910379409298 0.04384028000000006 0.08771429205718988" rpy="3.1415926535897927 -0.0955254270423661 1.5707963267948957" />
    <parent link="Chassis" />
    <child link="Mega-wsheeld-v5-1" />
  </joint>
  <joint name="Chassis_Rigid-14" type="fixed">
    <origin xyz="0.07864321620590699 0.09149999999999993 0.05855968205718996" rpy="3.806478941571966e-16 3.8064789415719715e-16 -1.5707963267948974" />
    <parent link="Chassis" />
    <child link="ZStepper" />
  </joint>
  <joint name="Chassis_Rigid-15" type="fixed">
    <origin xyz="0.191999996205907 0.13719999999999982 0.07175000205719004" rpy="3.806478941571966e-16 3.8064789415719715e-16 -1.5707963267948974" />
    <parent link="Chassis" />
    <child link="PI5" />
  </joint>
  <joint name="Chassis_Rigid-16" type="fixed">
    <origin xyz="0.23059999620590696 0.07739999999999982 0.08275000205719002" rpy="3.806478941571966e-16 3.8064789415719715e-16 -1.5707963267948974" />
    <parent link="Chassis" />
    <child link="LD06_LiDAR-1" />
  </joint>
  <joint name="Chassis_Rigid-17" type="fixed">
    <origin xyz="0.22470999620590695 0.08133999999999983 0.07275000205719001" rpy="-3.1415926535897927 3.8064789415719715e-16 -1.5707963267948974" />
    <parent link="Chassis" />
    <child link="BN0085" />
  </joint>
  <joint name="Chassis_Rigid-18" type="fixed">
    <origin xyz="0.21499999620590693 0.10189999999999982 0.06275000205719003" rpy="1.5707963267948957 -1.5707963267948961 0" />
    <parent link="Chassis" />
    <child link="rps-kamera-v2-2" />
  </joint>
  <joint name="Chassis_Rigid-19" type="fixed">
    <origin xyz="-0.1086300237940929 0.09150000000000011 0.006242222057189899" rpy="-1.5707963267948961 -1.989750355821705e-16 -2.419782393886413e-15" />
    <parent link="Chassis" />
    <child link="Unyaktig-batteri-mockup-v1-1" />
  </joint>
  <joint name="Chassis_Rigid-20" type="fixed">
    <origin xyz="0.129443206205907 0.06299999999999993 -0.0014403179428100232" rpy="-3.1415926535897927 3.8064789415719715e-16 -1.5707963267948974" />
    <parent link="Chassis" />
    <child link="RLeadscrew" />
  </joint>
  <joint name="Chassis_Rigid-21" type="fixed">
    <origin xyz="0.12944320620590702 0.11899999999999991 -0.001440317942810001" rpy="-3.1415926535897927 3.8064789415719715e-16 -1.5707963267948974" />
    <parent link="Chassis" />
    <child link="LLeadscrew" />
  </joint>
  <joint name="robotarm_z_joint" type="prismatic">
    <origin xyz="0.0 0.0 -0.500259" rpy="-3.141592653589793 9.860761315262648e-32 -8.292084300511961e-32" />
    <parent link="RLeadscrew" />
    <child link="Leadscrew-Rigg" />
    <axis xyz="4.930380657631324e-32 4.930380657631324e-32 1.0" />
    <limit lower="0.0" upper="0.25" effort="1000000" velocity="1000000" />
  </joint>
  <joint name="Leadscrew-Rigg_Rigid-23" type="fixed">
    <origin xyz="0.0 0.0 -0.3525" rpy="3.141592653589793 9.860761315262648e-32 -3.6134346367594863e-31" />
    <parent link="Leadscrew-Rigg" />
    <child link="LeadNutR" />
  </joint>
  <joint name="Leadscrew-Rigg_Rigid-25" type="fixed">
    <origin xyz="-0.043 -0.046 -0.32900000000000007" rpy="1.5707963267948966 9.860761315262648e-32 -9.736333669843527e-32" />
    <parent link="Leadscrew-Rigg" />
    <child link="Xstepper" />
  </joint>
  <joint name="Leadscrew-Rigg_Revolute-26" type="fixed">
    <origin xyz="-0.028000000000000004 -0.046 -0.32900000000000007" rpy="1.5707963267948966 2.4651903288156628e-31 -1.6412823737069552e-31" />
    <parent link="Leadscrew-Rigg" />
    <child link="Stepper-Gear-9R24.00-m2.741-1" />
  </joint>
  <joint name="Chassis_Rigid-27" type="fixed">
    <origin xyz="0.05794320620590703 0.12499999999999994 0.056559682057189975" rpy="-3.1415926535897927 3.8064789415719715e-16 -1.5707963267948974" />
    <parent link="Chassis" />
    <child link="StøtteStag-1" />
  </joint>
  <joint name="Leadscrew-Rigg_Revolute-28" type="fixed">
    <origin xyz="-0.028000000000000004 0.024000000000000004 -0.32900000000000007" rpy="1.5707963267948966 2.4651903288156628e-31 -1.6412823737069552e-31" />
    <parent link="Leadscrew-Rigg" />
    <child link="Gear-9R24.00-m2.741-1-1" />
  </joint>
  <joint name="robotarm_x_joint" type="prismatic">
    <origin xyz="-0.028000000000000004 -0.011000000000000006 -0.319" rpy="-9.860761315262648e-32 9.860761315262648e-32 -9.736333669843527e-32" />
    <parent link="Leadscrew-Rigg" />
    <child link="Gripper" />
    <axis xyz="-6.676490067226021e-32 1.0 0.0" />
    <limit lower="-0.07" upper="0.082" effort="1000000" velocity="1000000" />
  </joint>
  <joint name="Gripper_Rigid-30" type="fixed">
    <origin xyz="-0.01075 0.15057500000000001 -0.15480967999999998" rpy="3.141592653589793 -1.5707963267948966 0" />
    <parent link="Gripper" />
    <child link="Servo" />
  </joint>
  <joint name="Gripper_Rigid-31" type="fixed">
    <origin xyz="0.0 0.185 -0.15391655999999998" rpy="-3.141592653589793 1.5707963267948966 0" />
    <parent link="Gripper" />
    <child link="ABX00102-Dist-sensor" />
  </joint>
  <joint name="Servo_Revolute-32" type="fixed">
    <origin xyz="-8.881784197001253e-18 -0.01620000000000001 0.010749999999999989" rpy="1.5707963267948966 -1.5707963267948966 0" />
    <parent link="Servo" />
    <child link="Servo-Gear-8L30.00-m2.1651" />
  </joint>
  <joint name="Gripper_Slider-33" type="fixed">
    <origin xyz="-0.06508702 0.16570113000000003 -0.13650968" rpy="-3.141592653589793 -4.930380657631324e-32 -1.7755910601422187e-32" />
    <parent link="Gripper" />
    <child link="Top-Rack-200.0mm-R30.00-m2.1651" />
  </joint>
  <joint name="Gripper_Slider-34" type="fixed">
    <origin xyz="0.06492049 0.16570124 -0.17300967999999997" rpy="9.860761315262648e-32 -4.930380657631324e-32 -1.7755910601422187e-32" />
    <parent link="Gripper" />
    <child link="Bottom-Rack-200.0mm-L30.00-m2.1651" />
  </joint>
  <joint name="right_gripper_finger_joint" type="revolute">
    <origin xyz="0.05 0.19514971000000003 -0.15470968" rpy="-3.141592653589793 -5.473822126268811e-47 -2.0088433502773093e-31" />
    <parent link="Gripper" />
    <child link="Finger-R16L30.00-m2.1651Mirror" />
    <axis xyz="4.930380657631324e-32 4.930380657631326e-32 1.0000000000000007" />
    <limit lower="0.0" upper="8.0" effort="1000000" velocity="1000000" />
  </joint>
  <joint name="left_gripper_finger_joint" type="revolute">
    <origin xyz="-0.05 0.19514971000000003 -0.15470968" rpy="-3.141592653589793 -5.473822126268811e-47 -2.0088433502773093e-31" />
    <parent link="Gripper" />
    <child link="Finger-L-16L30.00-m2.1651" />
    <axis xyz="4.930380657631324e-32 4.930380657631326e-32 1.0000000000000007" />
    <limit lower="0.0" upper="8.0" effort="1000000" velocity="1000000" />
  </joint>
  <joint name="Chassis_Rigid-37" type="fixed">
    <origin xyz="-0.0600000037940929 0.16270000000000004 0.045250002057189945" rpy="1.570796326794897 3.8064789415719715e-16 -1.5707963267948974" />
    <parent link="Chassis" />
    <child link="M1" />
  </joint>
  <joint name="Chassis_Rigid-38" type="fixed">
    <origin xyz="-0.060000003794093 0.020300000000000092 0.04525000205718989" rpy="-1.5707963267948961 3.8064789415719715e-16 -1.5707963267948974" />
    <parent link="Chassis" />
    <child link="M2" />
  </joint>
  <joint name="Leadscrew-Rigg_Rigid-39" type="fixed">
    <origin xyz="-0.055999999999999994 0.0 -0.3525" rpy="-3.141592653589793 -2.9605947323337477e-16 -3.6891410794762184e-31" />
    <parent link="Leadscrew-Rigg" />
    <child link="LeadNutL" />
  </joint>
  <joint name="Chassis_Rigid-40" type="fixed">
    <origin xyz="0.07999578620590705 0.16719999999999993 0.059998152057189995" rpy="3.806478953373988e-16 -7.874654083273897e-05 -1.5707963267948974" />
    <parent link="Chassis" />
    <child link="LTracks" />
  </joint>
  <joint name="Chassis_Rigid-41" type="fixed">
    <origin xyz="0.07999578620590693 0.015799999999999967 0.05999815205718994" rpy="3.806478953373988e-16 -7.874654083292792e-05 -1.5707963267948974" />
    <parent link="Chassis" />
    <child link="RTracks" />
  </joint>
  <joint name="FLLegs_Revolute-42" type="continuous">
    <origin xyz="-0.01549999999999999 -0.05873733 -0.06652989999999999" rpy="-1.5707963267948957 -3.8761492285297827e-31 1.570796326794897" />
    <parent link="FLLegs" />
    <child link="RFWheelColision-1" />
    <axis xyz="3.8064789415719626e-16 8.049125398861859e-16 1.0" />
  </joint>
  <joint name="BLLegs_Revolute-43" type="continuous">
    <origin xyz="-0.01549999999999999 -0.05876532 0.06650282" rpy="1.5707963267948974 -3.8761492285297827e-31 1.570796326794897" />
    <parent link="BLLegs" />
    <child link="LBWheelColision" />
    <axis xyz="-3.8064789415719646e-16 8.049125398861855e-16 1.0" />
  </joint>
  <joint name="BRLegs_Revolute-44" type="continuous">
    <origin xyz="0.01549999999999999 0.05876532 -0.06650282" rpy="1.5707963267948974 -2.465190328815662e-31 -1.5707963267948961" />
    <parent link="BRLegs" />
    <child link="RBWheelColision" />
    <axis xyz="3.8064789415719646e-16 -8.049125398861855e-16 -1.0" />
  </joint>
  <joint name="FRLegs_Revolute-45" type="continuous">
    <origin xyz="0.01549999999999999 0.05873733 0.06652989999999999" rpy="1.5707963267948974 -2.465190328815662e-31 -1.5707963267948961" />
    <parent link="FRLegs" />
    <child link="RFWheelColision" />
    <axis xyz="3.8064789415719616e-16 -8.049125398861859e-16 -1.0" />
  </joint>
  <joint name="base_link_to_Chassis" type="fixed">
    <origin xyz="-0.06164321620590698 -0.09150000000000008 0.024978117942810095" rpy="0 0 0" />
    <parent link="base_link" />
    <child link="Chassis" />
  </joint>
  <link name="lidar_link" />
  <link name="imu_link" />
  <link name="camera_link" />
  <joint name="Chassis_to_lidar_link" type="fixed">
    <origin xyz="0.23059999620590696 0.07739999999999982 0.08275000205719002" rpy="0 0 0" />
    <parent link="Chassis" />
    <child link="lidar_link" />
  </joint>
  <joint name="Chassis_to_imu_link" type="fixed">
    <origin xyz="0.22470999620590695 0.08133999999999983 0.07275000205719001" rpy="0 0 0" />
    <parent link="Chassis" />
    <child link="imu_link" />
  </joint>
  <joint name="Chassis_to_camera_link" type="fixed">
    <origin xyz="0.21499999620590693 0.10189999999999982 0.06275000205719003" rpy="0 0 0" />
    <parent link="Chassis" />
    <child link="camera_link" />
  </joint>
</robot>
