<?xml version='1.0' encoding='utf-8'?>
<robot name="Gazebo">
    <link name="Drive-R">
        <inertial>
            <origin xyz="3.468719432439649e-05 -0.00013262225653649652 0.015437879033229535" rpy="0.0 -0.0 0.0" />
            <mass value="0.2431521857252203" />
            <inertia ixx="4.419056197472993e-05" iyy="4.458948248082411e-05" izz="4.7209875720485156e-05" ixy="-1.1717499915513997e-07" iyz="-1.4154759849866133e-07" ixz="4.138687373511053e-08" />
        </inertial>
        <visual name="Drive-R_visual">
            <origin xyz="-9.14823772291129e-16 -0.03000000007450601 -6.661338147750939e-18" rpy="-1.5707963267948968 3.7717412030879655e-30 -2.2401343147145716e-14" />
            <geometry>
                <mesh filename="meshes/Drive-R.stl" scale="0.001 0.001 0.001" />
            </geometry>
        </visual>
        <collision name="Drive-R_collision">
            <origin xyz="-9.14823772291129e-16 -0.03000000007450601 -6.661338147750939e-18" rpy="-1.5707963267948968 3.7717412030879655e-30 -2.2401343147145716e-14" />
            <geometry>
                <mesh filename="meshes/Drive-R.stl" scale="0.001 0.001 0.001" />
            </geometry>
        </collision>
    </link>
    <link name="MR">
        <inertial>
            <origin xyz="3.9598274219779196e-15 -0.02034205235406933 0.00011506187875827131" rpy="0.0 0.0 0.0" />
            <mass value="0.5167286386032199" />
            <inertia ixx="0.0002635465775872852" iyy="7.642695737140835e-05" izz="0.0002631399490233211" ixy="7.238240174911797e-17" iyz="2.3521178218531448e-06" ixz="-2.7774167347267215e-16" />
        </inertial>
        <visual name="MR_visual">
            <origin xyz="0.0 0.0 0.0" rpy="0.0 0.0 0.0" />
            <geometry>
                <mesh filename="meshes/MR.stl" scale="0.001 0.001 0.001" />
            </geometry>
        </visual>
        <collision name="MR_collision">
            <origin xyz="0.0 0.0 0.0" rpy="0.0 0.0 0.0" />
            <geometry>
                <mesh filename="meshes/MR.stl" scale="0.001 0.001 0.001" />
            </geometry>
        </collision>
    </link>
    <link name="Wheel-LB">
        <inertial>
            <origin xyz="-2.7760016507727413e-14 3.467369688888637e-16 0.015200251941424874" rpy="0.0 -0.0 0.0" />
            <mass value="0.14252315521285763" />
            <inertia ixx="2.9640812052605763e-05" iyy="2.9640792079172265e-05" izz="3.313001107052431e-05" ixy="-2.270793958672357e-11" iyz="3.39672268070281e-20" ixz="-5.431852884152377e-17" />
        </inertial>
        <visual name="Wheel-LB_visual">
            <origin xyz="0.0 4.440892098500638e-18 0.03019999999999996" rpy="-1.3994466596298774e-16 1.1704190886730506e-97 -4.803304891404735e-128" />
            <geometry>
                <mesh filename="meshes/Wheel-LB.stl" scale="0.001 0.001 0.001" />
            </geometry>
        </visual>
        <collision name="Wheel-LB_collision">
            <origin xyz="0.0 4.440892098500638e-18 0.03019999999999996" rpy="-1.3994466596298774e-16 1.1704190886730506e-97 -4.803304891404735e-128" />
            <geometry>
                <mesh filename="meshes/Wheel-LB.stl" scale="0.001 0.001 0.001" />
            </geometry>
        </collision>
    </link>
    <link name="Drive-L">
        <inertial>
            <origin xyz="3.468715518366139e-05 -0.0001326150756523159 -0.014937877711665343" rpy="0.0 -0.0 0.0" />
            <mass value="0.2431524600963511" />
            <inertia ixx="4.419062570802136e-05" iyy="4.458954575615667e-05" izz="4.7209984083190683e-05" ixy="-1.1717493858965505e-07" iyz="1.415571261051754e-07" ixz="-4.138692693677476e-08" />
        </inertial>
        <visual name="Drive-L_visual">
            <origin xyz="-9.14823772291129e-16 -0.03000000007450604 0.0005000076293945455" rpy="1.5707963267948968 -3.771741203087959e-30 -2.2401343147145716e-14" />
            <geometry>
                <mesh filename="meshes/Drive-L.stl" scale="0.001 0.001 0.001" />
            </geometry>
        </visual>
        <collision name="Drive-L_collision">
            <origin xyz="-9.14823772291129e-16 -0.03000000007450604 0.0005000076293945455" rpy="1.5707963267948968 -3.771741203087959e-30 -2.2401343147145716e-14" />
            <geometry>
                <mesh filename="meshes/Drive-L.stl" scale="0.001 0.001 0.001" />
            </geometry>
        </collision>
    </link>
    <link name="SLOTLBO">
        <inertial>
            <origin xyz="0.016575702698955273 -0.017699999999999997 -0.021515056987681122" rpy="0.0 0.0 0.0" />
            <mass value="0.019588847580050587" />
            <inertia ixx="7.377757013999264e-06" iyy="2.437262976791464e-05" izz="1.7076492952165507e-05" ixy="1.3552527156068805e-20" iyz="2.3291350295145e-37" ixz="8.723678794431038e-06" />
        </inertial>
        <visual name="SLOTLBO_visual">
            <origin xyz="0.0 0.0 0.0" rpy="0.0 0.0 0.0" />
            <geometry>
                <mesh filename="meshes/SLOTLBO.stl" scale="0.001 0.001 0.001" />
            </geometry>
        </visual>
        <collision name="SLOTLBO_collision">
            <origin xyz="0.0 0.0 0.0" rpy="0.0 0.0 0.0" />
            <geometry>
                <mesh filename="meshes/SLOTLBO.stl" scale="0.001 0.001 0.001" />
            </geometry>
        </collision>
    </link>
    <link name="ML">
        <inertial>
            <origin xyz="3.95982742197792e-15 -0.02034205235406933 -0.00011506187875826688" rpy="0.0 0.0 0.0" />
            <mass value="0.5167286386032199" />
            <inertia ixx="0.0002635465775872852" iyy="7.642695737140835e-05" izz="0.00026313994902331893" ixy="7.194872088012377e-17" iyz="-2.352117821852711e-06" ixz="2.777416734726721e-16" />
        </inertial>
        <visual name="ML_visual">
            <origin xyz="0.0 0.0 0.0" rpy="0.0 0.0 0.0" />
            <geometry>
                <mesh filename="meshes/ML.stl" scale="0.001 0.001 0.001" />
            </geometry>
        </visual>
        <collision name="ML_collision">
            <origin xyz="0.0 0.0 0.0" rpy="0.0 0.0 0.0" />
            <geometry>
                <mesh filename="meshes/ML.stl" scale="0.001 0.001 0.001" />
            </geometry>
        </collision>
    </link>
    <link name="Batterihold-v3">
        <inertial>
            <origin xyz="-0.2975005709902652 0.21328618965013116 0.0033017596654089953" rpy="0.0 0.0 0.0" />
            <mass value="0.2268973458607451" />
            <inertia ixx="0.0001286614107695111" iyy="0.00012736609243571177" izz="0.00023042986888546324" ixy="-4.511530704416978e-09" iyz="-4.223290413416279e-06" ixz="8.467046460259024e-10" />
        </inertial>
        <visual name="Batterihold-v3_visual">
            <origin xyz="0.0 0.0 0.0" rpy="0.0 0.0 0.0" />
            <geometry>
                <mesh filename="meshes/Batterihold-v3.stl" scale="0.001 0.001 0.001" />
            </geometry>
        </visual>
        <collision name="Batterihold-v3_collision">
            <origin xyz="0.0 0.0 0.0" rpy="0.0 0.0 0.0" />
            <geometry>
                <mesh filename="meshes/Batterihold-v3.stl" scale="0.001 0.001 0.001" />
            </geometry>
        </collision>
    </link>
    <link name="Unyaktig-batteri-mockup-v1">
        <inertial>
            <origin xyz="2.812678780476311e-19 -0.000792281376056143 0.02155752301184655" rpy="0.0 0.0 0.0" />
            <mass value="3.2626467645833337" />
            <inertia ixx="0.004205439111221465" iyy="0.002193073754250908" izz="0.005354058053271049" ixy="1.033327256091043e-18" iyz="6.604056105848373e-05" ixz="5.990599520398518e-18" />
        </inertial>
        <visual name="Unyaktig-batteri-mockup-v1_visual">
            <origin xyz="0.0 0.0 0.0" rpy="0.0 0.0 0.0" />
            <geometry>
                <mesh filename="meshes/Unyaktig-batteri-mockup-v1.stl" scale="0.001 0.001 0.001" />
            </geometry>
        </visual>
        <collision name="Unyaktig-batteri-mockup-v1_collision">
            <origin xyz="0.0 0.0 0.0" rpy="0.0 0.0 0.0" />
            <geometry>
                <mesh filename="meshes/Unyaktig-batteri-mockup-v1.stl" scale="0.001 0.001 0.001" />
            </geometry>
        </collision>
    </link>
    <link name="Stepper-1">
        <inertial>
            <origin xyz="-2.377222058688169e-16 -2.776297111215251e-06 0.07515489785203207" rpy="0.0 0.0 0.0" />
            <mass value="0.6982155425981512" />
            <inertia ixx="0.0003009322348135699" iyy="0.00030093805555665015" izz="0.0001739036568460372" ixy="-1.670747045868771e-20" iyz="-8.559222926167172e-08" ixz="-2.597258417867786e-18" />
        </inertial>
        <visual name="Stepper-1_visual">
            <origin xyz="0.0 0.0 0.0" rpy="0.0 0.0 0.0" />
            <geometry>
                <mesh filename="meshes/Stepper-1.stl" scale="0.001 0.001 0.001" />
            </geometry>
        </visual>
        <collision name="Stepper-1_collision">
            <origin xyz="0.0 0.0 0.0" rpy="0.0 0.0 0.0" />
            <geometry>
                <mesh filename="meshes/Stepper-1.stl" scale="0.001 0.001 0.001" />
            </geometry>
        </collision>
    </link>
    <link name="SLOTLFI">
        <inertial>
            <origin xyz="0.03992928458075967 -0.02346418770201589 0.002499999999999929" rpy="0.0 -0.0 0.0" />
            <mass value="0.019589158482731676" />
            <inertia ixx="7.370392750968499e-06" iyy="1.708489279065152e-05" izz="2.4373664047941965e-05" ixy="8.719843893117687e-06" iyz="-1.3552527156068805e-20" ixz="-5.421010862427522e-20" />
        </inertial>
        <visual name="SLOTLFI_visual">
            <origin xyz="-0.1035 -0.045 0.020199999999999944" rpy="1.5707963267948966 1.1704190886730506e-97 1.868155825118626e-129" />
            <geometry>
                <mesh filename="meshes/SLOTLFI.stl" scale="0.001 0.001 0.001" />
            </geometry>
        </visual>
        <collision name="SLOTLFI_collision">
            <origin xyz="-0.1035 -0.045 0.020199999999999944" rpy="1.5707963267948966 1.1704190886730506e-97 1.868155825118626e-129" />
            <geometry>
                <mesh filename="meshes/SLOTLFI.stl" scale="0.001 0.001 0.001" />
            </geometry>
        </collision>
    </link>
    <link name="Midsection">
        <inertial>
            <origin xyz="0.09218106044750891 0.09171079589706707 0.023717444279737952" rpy="0.0 0.0 0.0" />
            <mass value="3.342899967628929" />
            <inertia ixx="0.005133772281246302" iyy="0.029680610024049127" izz="0.03033761548743684" ixy="0.00010267079804601037" iyz="6.815405417486334e-06" ixz="-0.0006424929595211602" />
        </inertial>
        <visual name="Midsection_visual">
            <origin xyz="0.0 0.0 0.0" rpy="0.0 0.0 0.0" />
            <geometry>
                <mesh filename="meshes/Midsection.stl" scale="0.001 0.001 0.001" />
            </geometry>
        </visual>
        <collision name="Midsection_collision">
            <origin xyz="0.0 0.0 0.0" rpy="0.0 0.0 0.0" />
            <geometry>
                <mesh filename="meshes/Midsection.stl" scale="0.001 0.001 0.001" />
            </geometry>
        </collision>
    </link>
    <link name="Lidar">
        <inertial>
            <origin xyz="0.2157049999999998 0.09149999999999991 0.09685545178026617" rpy="0.0 0.0 0.0" />
            <mass value="0.33873170539643604" />
            <inertia ixx="6.664120861013707e-05" iyy="6.664120861014228e-05" izz="7.512110553573731e-05" ixy="0.0" iyz="-4.336808689942018e-19" ixz="-2.6020852139652106e-18" />
        </inertial>
        <visual name="Lidar_visual">
            <origin xyz="0.0 0.0 0.0" rpy="0.0 0.0 0.0" />
            <geometry>
                <mesh filename="meshes/Lidar.stl" scale="0.001 0.001 0.001" />
            </geometry>
        </visual>
        <collision name="Lidar_collision">
            <origin xyz="0.0 0.0 0.0" rpy="0.0 0.0 0.0" />
            <geometry>
                <mesh filename="meshes/Lidar.stl" scale="0.001 0.001 0.001" />
            </geometry>
        </collision>
    </link>
    <link name="IMU">
        <inertial>
            <origin xyz="0.21581999999999985 0.09149999995566864 0.07257499992549436" rpy="0.0 0.0 0.0" />
            <mass value="0.007520791409999992" />
            <inertia ixx="4.060490950574423e-07" iyy="3.292239601111746e-07" izz="7.31860496066346e-07" ixy="2.710505431213761e-20" iyz="-1.3552527156068805e-20" ixz="0.0" />
        </inertial>
        <visual name="IMU_visual">
            <origin xyz="0.0 0.0 0.0" rpy="0.0 0.0 0.0" />
            <geometry>
                <mesh filename="meshes/IMU.stl" scale="0.001 0.001 0.001" />
            </geometry>
        </visual>
        <collision name="IMU_collision">
            <origin xyz="0.0 0.0 0.0" rpy="0.0 0.0 0.0" />
            <geometry>
                <mesh filename="meshes/IMU.stl" scale="0.001 0.001 0.001" />
            </geometry>
        </collision>
    </link>
    <link name="SLOTRFO">
        <inertial>
            <origin xyz="0.14342928458075968 -0.017699999999999994 0.021535812297984104" rpy="0.0 0.0 0.0" />
            <mass value="0.01958915848273168" />
            <inertia ixx="7.370392750968643e-06" iyy="2.437366404794202e-05" izz="1.7084892790651413e-05" ixy="6.776263578034403e-21" iyz="8.470329472543003e-22" ixz="8.719843893117701e-06" />
        </inertial>
        <visual name="SLOTRFO_visual">
            <origin xyz="0.0 0.0 0.0" rpy="0.0 0.0 0.0" />
            <geometry>
                <mesh filename="meshes/SLOTRFO.stl" scale="0.001 0.001 0.001" />
            </geometry>
        </visual>
        <collision name="SLOTRFO_collision">
            <origin xyz="0.0 0.0 0.0" rpy="0.0 0.0 0.0" />
            <geometry>
                <mesh filename="meshes/SLOTRFO.stl" scale="0.001 0.001 0.001" />
            </geometry>
        </collision>
    </link>
    <link name="SLOTRBO">
        <inertial>
            <origin xyz="0.016575702698955273 -0.017699999999999997 0.021515056987681122" rpy="0.0 0.0 0.0" />
            <mass value="0.019588847580050583" />
            <inertia ixx="7.377757013999288e-06" iyy="2.437262976791462e-05" izz="1.7076492952165545e-05" ixy="-8.470329472543003e-22" iyz="-8.470329472543003e-22" ixz="-8.72367879443103e-06" />
        </inertial>
        <visual name="SLOTRBO_visual">
            <origin xyz="0.0 0.0 0.0" rpy="0.0 0.0 0.0" />
            <geometry>
                <mesh filename="meshes/SLOTRBO.stl" scale="0.001 0.001 0.001" />
            </geometry>
        </visual>
        <collision name="SLOTRBO_collision">
            <origin xyz="0.0 0.0 0.0" rpy="0.0 0.0 0.0" />
            <geometry>
                <mesh filename="meshes/SLOTRBO.stl" scale="0.001 0.001 0.001" />
            </geometry>
        </collision>
    </link>
    <link name="R-FIXTURE">
        <inertial>
            <origin xyz="0.08005840992655662 0.0020233346999058194 0.043728741102044534" rpy="0.0 0.0 0.0" />
            <mass value="0.1336063441196063" />
            <inertia ixx="1.9728072698204117e-05" iyy="0.0003942707152908931" izz="0.0003918756278702305" ixy="2.989545846269234e-09" iyz="-1.8013826305588445e-07" ixz="1.3318873767054597e-07" />
        </inertial>
        <visual name="R-FIXTURE_visual">
            <origin xyz="0.0 0.0 0.0" rpy="0.0 0.0 0.0" />
            <geometry>
                <mesh filename="meshes/R-FIXTURE.stl" scale="0.001 0.001 0.001" />
            </geometry>
        </visual>
        <collision name="R-FIXTURE_collision">
            <origin xyz="0.0 0.0 0.0" rpy="0.0 0.0 0.0" />
            <geometry>
                <mesh filename="meshes/R-FIXTURE.stl" scale="0.001 0.001 0.001" />
            </geometry>
        </collision>
    </link>
    <link name="L-FIXTURE">
        <inertial>
            <origin xyz="0.08002094360672342 0.18099177132301075 0.04371725048070878" rpy="0.0 0.0 0.0" />
            <mass value="0.13375646810400504" />
            <inertia ixx="1.977801525824066e-05" iyy="0.0003945307937078886" izz="0.00039215677241567423" ixy="7.339309911094487e-08" iyz="2.0366145113111592e-07" ixz="7.610122844224501e-08" />
        </inertial>
        <visual name="L-FIXTURE_visual">
            <origin xyz="0.0 0.0 0.0" rpy="0.0 0.0 0.0" />
            <geometry>
                <mesh filename="meshes/L-FIXTURE.stl" scale="0.001 0.001 0.001" />
            </geometry>
        </visual>
        <collision name="L-FIXTURE_collision">
            <origin xyz="0.0 0.0 0.0" rpy="0.0 0.0 0.0" />
            <geometry>
                <mesh filename="meshes/L-FIXTURE.stl" scale="0.001 0.001 0.001" />
            </geometry>
        </collision>
    </link>
    <link name="Body-R">
        <inertial>
            <origin xyz="0.08493777982513029 0.030995458501583785 0.036532552449082226" rpy="0.0 0.0 0.0" />
            <mass value="0.17531132738139585" />
            <inertia ixx="6.791665160125457e-05" iyy="0.0014003099310863382" izz="0.0013431920719940013" ixy="1.1767546588659788e-05" iyz="5.648185064282039e-06" ixz="-2.385089292118866e-05" />
        </inertial>
        <visual name="Body-R_visual">
            <origin xyz="0.0 0.0 0.0" rpy="0.0 0.0 0.0" />
            <geometry>
                <mesh filename="meshes/Body-R.stl" scale="0.001 0.001 0.001" />
            </geometry>
        </visual>
        <collision name="Body-R_collision">
            <origin xyz="0.0 0.0 0.0" rpy="0.0 0.0 0.0" />
            <geometry>
                <mesh filename="meshes/Body-R.stl" scale="0.001 0.001 0.001" />
            </geometry>
        </collision>
    </link>
    <link name="Body-L">
        <inertial>
            <origin xyz="0.08493775530257533 0.1520045436208202 0.03653254732136139" rpy="0.0 0.0 0.0" />
            <mass value="0.1753116596229364" />
            <inertia ixx="6.791667997417712e-05" iyy="0.001400311846833165" izz="0.0013431940071499011" ixy="-1.1767551261003626e-05" iyz="-5.648185609074033e-06" ixz="-2.3851048974989075e-05" />
        </inertial>
        <visual name="Body-L_visual">
            <origin xyz="0.0 0.0 0.0" rpy="0.0 0.0 0.0" />
            <geometry>
                <mesh filename="meshes/Body-L.stl" scale="0.001 0.001 0.001" />
            </geometry>
        </visual>
        <collision name="Body-L_collision">
            <origin xyz="0.0 0.0 0.0" rpy="0.0 0.0 0.0" />
            <geometry>
                <mesh filename="meshes/Body-L.stl" scale="0.001 0.001 0.001" />
            </geometry>
        </collision>
    </link>
    <link name="SLOTRFI">
        <inertial>
            <origin xyz="0.03992928458075967 0.023464187702015894 0.0025" rpy="0.0 -0.0 0.0" />
            <mass value="0.01958915848273168" />
            <inertia ixx="7.370392750968641e-06" iyy="1.708489279065136e-05" izz="2.437366404794202e-05" ixy="-8.719843893117701e-06" iyz="3.3881317890172014e-21" ixz="-2.0328790734103208e-20" />
        </inertial>
        <visual name="SLOTRFI_visual">
            <origin xyz="-0.1035 0.045 0.020199999999999996" rpy="1.5707963267948966 1.1704190886730506e-97 1.868155825118626e-129" />
            <geometry>
                <mesh filename="meshes/SLOTRFI.stl" scale="0.001 0.001 0.001" />
            </geometry>
        </visual>
        <collision name="SLOTRFI_collision">
            <origin xyz="-0.1035 0.045 0.020199999999999996" rpy="1.5707963267948966 1.1704190886730506e-97 1.868155825118626e-129" />
            <geometry>
                <mesh filename="meshes/SLOTRFI.stl" scale="0.001 0.001 0.001" />
            </geometry>
        </collision>
    </link>
    <link name="SLOTRBI">
        <inertial>
            <origin xyz="-0.03991822730104472 0.023481243012318877 0.002499999999999998" rpy="0.0 -0.0 0.0" />
            <mass value="0.019588847580050583" />
            <inertia ixx="7.377757013999284e-06" iyy="1.707649295216554e-05" izz="2.437262976791462e-05" ixy="8.723678794431028e-06" iyz="-3.3881317890172014e-21" ixz="-3.3881317890172014e-21" />
        </inertial>
        <visual name="SLOTRBI_visual">
            <origin xyz="-0.05649393 0.044996299999999996 0.020199999999999996" rpy="1.5707963267948966 1.1704190886730506e-97 1.868155825118626e-129" />
            <geometry>
                <mesh filename="meshes/SLOTRBI.stl" scale="0.001 0.001 0.001" />
            </geometry>
        </visual>
        <collision name="SLOTRBI_collision">
            <origin xyz="-0.05649393 0.044996299999999996 0.020199999999999996" rpy="1.5707963267948966 1.1704190886730506e-97 1.868155825118626e-129" />
            <geometry>
                <mesh filename="meshes/SLOTRBI.stl" scale="0.001 0.001 0.001" />
            </geometry>
        </collision>
    </link>
    <link name="WheelRB">
        <inertial>
            <origin xyz="-2.7746693831431914e-14 2.410543080531005e-16 -0.015200212388717506" rpy="0.0 -0.0 0.0" />
            <mass value="0.14253267377489354" />
            <inertia ixx="2.9642118226419924e-05" iyy="2.9641896767983483e-05" izz="3.313069220622944e-05" ixy="3.2986090963689213e-11" iyz="-7.579523112009865e-20" ixz="-5.4555235465997406e-17" />
        </inertial>
        <visual name="WheelRB_visual">
            <origin xyz="0.0 4.440892098500638e-18 -0.0302" rpy="1.3994466596298774e-16 -1.1704190886730506e-97 -4.803304891404735e-128" />
            <geometry>
                <mesh filename="meshes/WheelRB.stl" scale="0.001 0.001 0.001" />
            </geometry>
        </visual>
        <collision name="WheelRB_collision">
            <origin xyz="0.0 4.440892098500638e-18 -0.0302" rpy="1.3994466596298774e-16 -1.1704190886730506e-97 -4.803304891404735e-128" />
            <geometry>
                <mesh filename="meshes/WheelRB.stl" scale="0.001 0.001 0.001" />
            </geometry>
        </collision>
    </link>
    <link name="WheelRF">
        <inertial>
            <origin xyz="5.754779053290804e-10 5.108396536118374e-10 -0.015200212388717516" rpy="0.0 -0.0 0.0" />
            <mass value="0.14253267377489354" />
            <inertia ixx="2.964211822641992e-05" iyy="2.9641896767983178e-05" izz="3.3130692206229106e-05" ixy="3.29860909639401e-11" iyz="-7.530699290073521e-20" ixz="-5.455523567279256e-17" />
        </inertial>
        <visual name="WheelRF_visual">
            <origin xyz="5.755056520229118e-10 5.108394149008766e-10 -0.030200000000000015" rpy="-4.930380657631314e-32 -1.1704190886730506e-97 -2.8853058180580834e-129" />
            <geometry>
                <mesh filename="meshes/WheelRF.stl" scale="0.001 0.001 0.001" />
            </geometry>
        </visual>
        <collision name="WheelRF_collision">
            <origin xyz="5.755056520229118e-10 5.108394149008766e-10 -0.030200000000000015" rpy="-4.930380657631314e-32 -1.1704190886730506e-97 -2.8853058180580834e-129" />
            <geometry>
                <mesh filename="meshes/WheelRF.stl" scale="0.001 0.001 0.001" />
            </geometry>
        </collision>
    </link>
    <link name="WheelRT">
        <inertial>
            <origin xyz="-2.7746693831431914e-14 -2.3980817331903383e-16 -0.01579978761128249" rpy="0.0 -0.0 0.0" />
            <mass value="0.14253267377489354" />
            <inertia ixx="2.9642118226419945e-05" iyy="2.9641896767984045e-05" izz="3.313069220623084e-05" ixy="-3.2986090855308126e-11" iyz="-7.57949731185402e-20" ixz="5.4555234845611947e-17" />
        </inertial>
        <visual name="WheelRT_visual">
            <origin xyz="0.0 0.0 -0.0008000000000000007" rpy="-3.141592653589793 1.1704190886730506e-97 1.868155825118626e-129" />
            <geometry>
                <mesh filename="meshes/WheelRT.stl" scale="0.001 0.001 0.001" />
            </geometry>
        </visual>
        <collision name="WheelRT_collision">
            <origin xyz="0.0 0.0 -0.0008000000000000007" rpy="-3.141592653589793 1.1704190886730506e-97 1.868155825118626e-129" />
            <geometry>
                <mesh filename="meshes/WheelRT.stl" scale="0.001 0.001 0.001" />
            </geometry>
        </collision>
    </link>
    <link name="WheelLF">
        <inertial>
            <origin xyz="5.754779053290804e-10 5.108397592955283e-10 0.015200259570819448" rpy="0.0 -0.0 0.0" />
            <mass value="0.14252315521285763" />
            <inertia ixx="2.964081205260663e-05" iyy="2.9640792079172265e-05" izz="3.313001107052311e-05" ixy="-2.270793958664476e-11" iyz="3.3457801416544863e-20" ixz="-5.551115123125783e-17" />
        </inertial>
        <visual name="WheelLF_visual">
            <origin xyz="5.755056520229118e-10 5.108394149008766e-10 0.030200007629394534" rpy="2.4651903288156526e-32 1.1704190886730506e-97 -5.006734889992618e-128" />
            <geometry>
                <mesh filename="meshes/WheelLF.stl" scale="0.001 0.001 0.001" />
            </geometry>
        </visual>
        <collision name="WheelLF_collision">
            <origin xyz="5.755056520229118e-10 5.108394149008766e-10 0.030200007629394534" rpy="2.4651903288156526e-32 1.1704190886730506e-97 -5.006734889992618e-128" />
            <geometry>
                <mesh filename="meshes/WheelLF.stl" scale="0.001 0.001 0.001" />
            </geometry>
        </collision>
    </link>
    <link name="WheelLT">
        <inertial>
            <origin xyz="-2.7746693831431914e-14 3.4638958368304885e-16 -0.01579974805857514" rpy="0.0 -0.0 0.0" />
            <mass value="0.14252315521285763" />
            <inertia ixx="2.9640812052604895e-05" iyy="2.9640792079172265e-05" izz="3.313001107052571e-05" ixy="-2.2707939695276735e-11" iyz="-2.168404344971009e-19" ixz="-5.4643789493269423e-17" />
        </inertial>
        <visual name="WheelLT_visual">
            <origin xyz="0.0 0.0 -0.000800000000000054" rpy="-1.3994466596298734e-16 1.1704190886730506e-97 1.868155825118626e-129" />
            <geometry>
                <mesh filename="meshes/WheelLT.stl" scale="0.001 0.001 0.001" />
            </geometry>
        </visual>
        <collision name="WheelLT_collision">
            <origin xyz="0.0 0.0 -0.000800000000000054" rpy="-1.3994466596298734e-16 1.1704190886730506e-97 1.868155825118626e-129" />
            <geometry>
                <mesh filename="meshes/WheelLT.stl" scale="0.001 0.001 0.001" />
            </geometry>
        </collision>
    </link>
    <link name="SLOTLFO">
        <inertial>
            <origin xyz="0.14342928458075968 -0.017699999999999997 -0.02153581229798411" rpy="0.0 0.0 0.0" />
            <mass value="0.019589158482731676" />
            <inertia ixx="7.370392750968716e-06" iyy="2.4373664047941965e-05" izz="1.7084892790651413e-05" ixy="2.7836229468064333e-37" iyz="1.3552527156068805e-20" ixz="-8.719843893117687e-06" />
        </inertial>
        <visual name="SLOTLFO_visual">
            <origin xyz="0.0 0.0 0.0" rpy="0.0 0.0 0.0" />
            <geometry>
                <mesh filename="meshes/SLOTLFO.stl" scale="0.001 0.001 0.001" />
            </geometry>
        </visual>
        <collision name="SLOTLFO_collision">
            <origin xyz="0.0 0.0 0.0" rpy="0.0 0.0 0.0" />
            <geometry>
                <mesh filename="meshes/SLOTLFO.stl" scale="0.001 0.001 0.001" />
            </geometry>
        </collision>
    </link>
    <link name="SLOTLBI">
        <inertial>
            <origin xyz="-0.039918227301044724 -0.023481243012318877 0.002499999999999929" rpy="0.0 -0.0 0.0" />
            <mass value="0.019588847580050587" />
            <inertia ixx="7.377757013999264e-06" iyy="1.7076492952165616e-05" izz="2.437262976791464e-05" ixy="-8.723678794431038e-06" iyz="-2.3291350295144658e-37" ixz="2.0328790734103208e-20" />
        </inertial>
        <visual name="SLOTLBI_visual">
            <origin xyz="-0.05649393 -0.044996299999999996 0.020199999999999944" rpy="1.5707963267948966 1.1704190886730506e-97 1.868155825118626e-129" />
            <geometry>
                <mesh filename="meshes/SLOTLBI.stl" scale="0.001 0.001 0.001" />
            </geometry>
        </visual>
        <collision name="SLOTLBI_collision">
            <origin xyz="-0.05649393 -0.044996299999999996 0.020199999999999944" rpy="1.5707963267948966 1.1704190886730506e-97 1.868155825118626e-129" />
            <geometry>
                <mesh filename="meshes/SLOTLBI.stl" scale="0.001 0.001 0.001" />
            </geometry>
        </collision>
    </link>
    <joint name="MR_Revolute-23" type="continuous">
        <origin xyz="8.881784197001253e-17 -0.05850000000000005 0.007000000074505981" rpy="1.5707963267948966 -2.2401343147145722e-14 5.55111512312572e-17" />
        <parent link="MR" />
        <child link="Drive-R" />
        <axis xyz="2.688924019593644e-45 1.5326701953552687e-46 1.0" />
    </joint>
    <joint name="Body-R_Revolute-24" type="continuous">
        <origin xyz="0.22 0.0158 0.045" rpy="-1.5707963267948966 -0.0 0.0" />
        <parent link="Body-R" />
        <child link="WheelRT" />
        <axis xyz="0.0 0.0 1.0" />
    </joint>
    <joint name="SLOTRFO_Revolute-25" type="continuous">
        <origin xyz="0.18001517 -0.0152 3.635e-05" rpy="1.5707963267948966 -0.0 0.0" />
        <parent link="SLOTRFO" />
        <child link="WheelRF" />
        <axis xyz="0.0 -3.944304526105059e-31 1.0" />
    </joint>
    <joint name="SLOTRBO_Revolute-26" type="continuous">
        <origin xyz="-0.02 -0.0152 0.0" rpy="1.5707963267948966 -0.0 0.0" />
        <parent link="SLOTRBO" />
        <child link="WheelRB" />
        <axis xyz="0.0 -3.944304526105059e-31 1.0" />
    </joint>
    <joint name="R-FIXTURE_Revolute-27" type="continuous">
        <origin xyz="0.05649393 0.0158 0.044996299999999996" rpy="-1.5707963267948966 -0.0 0.0" />
        <parent link="R-FIXTURE" />
        <child link="SLOTRBI" />
        <axis xyz="0.0 0.0 1.0" />
    </joint>
    <joint name="R-FIXTURE_Revolute-28" type="continuous">
        <origin xyz="0.1035 0.0158 0.045" rpy="-1.5707963267948966 -0.0 0.0" />
        <parent link="R-FIXTURE" />
        <child link="SLOTRFI" />
        <axis xyz="0.0 0.0 1.0" />
    </joint>
    <joint name="ML_Revolute-29" type="continuous">
        <origin xyz="8.881784197001253e-17 -0.059000000000000004 -0.007000000074505977" rpy="-1.5707963267948966 2.2401343147145722e-14 5.55111512312572e-17" />
        <parent link="ML" />
        <child link="Drive-L" />
        <axis xyz="-3.404038803619725e-45 1.5326701953552687e-46 -1.0" />
    </joint>
    <joint name="SLOTLBO_Revolute-30" type="continuous">
        <origin xyz="-0.02 -0.01519999999999996 -4.852273654216742e-34" rpy="-1.5707963267948966 -1.868155825118626e-129 1.1704190886730506e-97" />
        <parent link="SLOTLBO" />
        <child link="Wheel-LB" />
        <axis xyz="-5.9636863764438586e-161 -3.944304526105059e-31 -1.0" />
    </joint>
    <joint name="L-FIXTURE_Revolute-31" type="continuous">
        <origin xyz="0.05649393 0.1672 0.044996299999999996" rpy="1.5707963267948966 -0.0 0.0" />
        <parent link="L-FIXTURE" />
        <child link="SLOTLBI" />
        <axis xyz="0.0 -3.19228529882681e-32 1.0" />
    </joint>
    <joint name="L-FIXTURE_Revolute-32" type="continuous">
        <origin xyz="0.1035 0.1672 0.045" rpy="1.5707963267948966 -0.0 0.0" />
        <parent link="L-FIXTURE" />
        <child link="SLOTLFI" />
        <axis xyz="0.0 -3.19228529882681e-32 1.0" />
    </joint>
    <joint name="SLOTLFO_Revolute-33" type="continuous">
        <origin xyz="0.18001517 -0.01519999999999996 -3.635e-05" rpy="-1.5707963267948966 -1.868155825118626e-129 1.1704190886730506e-97" />
        <parent link="SLOTLFO" />
        <child link="WheelLF" />
        <axis xyz="-5.9636863764438586e-161 -3.944304526105059e-31 -1.0" />
    </joint>
    <joint name="Body-L_Revolute-34" type="continuous">
        <origin xyz="0.22 0.1672 0.045" rpy="1.5707963267948966 -0.0 0.0" />
        <parent link="Body-L" />
        <child link="WheelLT" />
        <axis xyz="0.0 -3.19228529882681e-32 1.0" />
    </joint>
</robot>