<sdf xmlns:gz="https://gazebosim.org/schemas" version="1.11">
  <model name="tracked_robot">
    <link name="base_link">
      <inertial>
        <pose>-0.01486625534524842 -0.0002290471873852562 0.1079008108510118 0 0 0</pose>
        <mass>3.7449030614111409</mass>
        <inertia>
          <ixx>0.050590526999619703</ixx>
          <ixy>-0.00015728684728166871</ixy>
          <ixz>-0.01010908826598406</ixz>
          <iyy>0.081940441237411982</iyy>
          <iyz>-0.0003793639125789277</iyz>
          <izz>0.05011532405785666</izz>
        </inertia>
      </inertial>
      <visual name="base_link_fixed_joint_lump__Chassis_visual_visual">
        <pose>-0.063250000000000001 -0.091499999999999998 0.02306692504882827 0 0 0</pose>
        <geometry>
          <mesh>
            <scale>0.001 0.001 0.001</scale>
            <uri>meshes/Chassis.stl</uri>
          </mesh>
        </geometry>
      </visual>
      <visual name="base_link_fixed_joint_lump__LDriveWheel_visual_visual_1">
        <pose>-0.1232500000000003 0.076200000000000018 0.038316924974322257 -3.1415926535897931 -3.3306690738754672e-16 -1.8873791418627661e-15</pose>
        <geometry>
          <mesh>
            <scale>0.001 0.001 0.001</scale>
            <uri>meshes/LDriveWheel.stl</uri>
          </mesh>
        </geometry>
      </visual>
      <visual name="base_link_fixed_joint_lump__LTWheel_visual_visual_2">
        <pose>0.15674999999999989 0.076199998855590645 0.068066925048828261 1.570796326794897 -4.5437038700002179e-16 -1.8674535998154189e-15</pose>
        <geometry>
          <mesh>
            <scale>0.001 0.001 0.001</scale>
            <uri>meshes/LTWheel.stl</uri>
          </mesh>
        </geometry>
      </visual>
      <visual name="base_link_fixed_joint_lump__RTWheel_visual_visual_3">
        <pose>0.15675000000000011 -0.076200000000000004 0.06806692504882822 1.570796326794897 -4.8639851103231072e-16 -1.8687401769933521e-15</pose>
        <geometry>
          <mesh>
            <scale>0.001 0.001 0.001</scale>
            <uri>meshes/RTWheel.stl</uri>
          </mesh>
        </geometry>
      </visual>
      <visual name="base_link_fixed_joint_lump__RDriveWheel_visual_visual_4">
        <pose>-0.1232500000000003 -0.076199999999999962 0.03831692497432225 -2.7755575615628859e-16 -4.9960036108132074e-16 -1.8873791418627661e-15</pose>
        <geometry>
          <mesh>
            <scale>0.001 0.001 0.001</scale>
            <uri>meshes/RDriveWheel.stl</uri>
          </mesh>
        </geometry>
      </visual>
      <visual name="base_link_fixed_joint_lump__Mega-wsheeld-v5-1_visual_visual_5">
        <pose>-0.1136123541507145 -0.024002657566231791 0.1927972815115068 0.09552542704236483 2.4980018054066022e-16 1.5707963267948972</pose>
        <geometry>
          <mesh>
            <scale>0.001 0.001 0.001</scale>
            <uri>meshes/Mega-wsheeld-v5-1.stl</uri>
          </mesh>
        </geometry>
      </visual>
      <visual name="base_link_fixed_joint_lump__ZStepper_visual_visual_6">
        <pose>0.015393216205906991 -5.5511151231257827e-17 0.01332660651274451 -5.5511151231258295e-17 -2.7755575615629012e-17 7.7037197775490358e-34</pose>
        <geometry>
          <mesh>
            <scale>0.001 0.001 0.001</scale>
            <uri>meshes/ZStepper.stl</uri>
          </mesh>
        </geometry>
      </visual>
      <visual name="base_link_fixed_joint_lump__PI5_visual_visual_7">
        <pose>0.1042499999999974 0.0067000000000014409 0.094716924974322672 1.570796326794897 0 1.5707963267948957</pose>
        <geometry>
          <mesh>
            <scale>0.001 0.001 0.001</scale>
            <uri>meshes/PI5.stl</uri>
          </mesh>
        </geometry>
      </visual>
      <visual name="base_link_fixed_joint_lump__LD06_LiDAR-1_visual_visual_8">
        <pose>0.1532500000000008 1.165734175856414e-15 0.10581692695622261 1.570796326794897 0 1.5707963267948957</pose>
        <geometry>
          <mesh>
            <scale>0.001 0.001 0.001</scale>
            <uri>meshes/LD06_LiDAR-1.stl</uri>
          </mesh>
        </geometry>
      </visual>
      <visual name="base_link_fixed_joint_lump__BN0085_visual_visual_9">
        <pose>0.1525699999999999 -4.4331330273372771e-11 0.095816924974322648 -4.4373425918681914e-31 2.454633718507182e-16 1.570796326794897</pose>
        <geometry>
          <mesh>
            <scale>0.001 0.001 0.001</scale>
            <uri>meshes/BN0085.stl</uri>
          </mesh>
        </geometry>
      </visual>
      <visual name="base_link_fixed_joint_lump__rps-kamera-v2-2_visual_visual_10">
        <pose>0.15274999999999991 -0.00010000000000000291 0.075816924974322658 1.570796326794897 -8.8817841970012523e-16 1.5707963267948957</pose>
        <geometry>
          <mesh>
            <scale>0.001 0.001 0.001</scale>
            <uri>meshes/rps-kamera-v2-2.stl</uri>
          </mesh>
        </geometry>
      </visual>
      <visual name="base_link_fixed_joint_lump__Unyaktig-batteri-mockup-v1-1_visual_visual_11">
        <pose>-0.20888002569571601 3.8857805861880479e-16 0.07780915001349456 -1.5707963267948972 4.9960036108132044e-16 -1.570796326794881</pose>
        <geometry>
          <mesh>
            <scale>0.001 0.001 0.001</scale>
            <uri>meshes/Unyaktig-batteri-mockup-v1-1.stl</uri>
          </mesh>
        </geometry>
      </visual>
      <visual name="base_link_fixed_joint_lump__RLeadscrew_visual_visual_12">
        <pose>0.06619320312723212 -0.028499456255732011 0.5216266065127444 -1.8590599560760131e-16 -2.06285452644195e-16 -2.390060563115415e-32</pose>
        <geometry>
          <mesh>
            <scale>0.001 0.001 0.001</scale>
            <uri>meshes/RLeadscrew.stl</uri>
          </mesh>
        </geometry>
      </visual>
      <visual name="base_link_fixed_joint_lump__LLeadscrew_visual_visual_13">
        <pose>0.066193203127232092 0.0274994562556817 0.5216266065127444 -3.1415926535897931 -2.0628545264419451e-16 -7.7181756391690859e-32</pose>
        <geometry>
          <mesh>
            <scale>0.001 0.001 0.001</scale>
            <uri>meshes/LLeadscrew.stl</uri>
          </mesh>
        </geometry>
      </visual>
      <visual name="base_link_fixed_joint_lump__StøtteStag-1_visual_visual_14">
        <pose>0.059793203127232103 0.016999999523124799 0.17612660460539589 -1.8590599560760131e-16 -2.2887797940471748e-16 -2.0750540995624424e-32</pose>
        <geometry>
          <mesh>
            <scale>0.001 0.001 0.001</scale>
            <uri>meshes/StøtteStag-1.stl</uri>
          </mesh>
        </geometry>
      </visual>
      <visual name="base_link_fixed_joint_lump__M1_visual_visual_15">
        <pose>-0.1232500000000001 0.018199999999999949 0.061316924974322277 -3.1415926535897931 -4.4408920985006262e-16 -1.7763568394002501e-15</pose>
        <geometry>
          <mesh>
            <scale>0.001 0.001 0.001</scale>
            <uri>meshes/M1.stl</uri>
          </mesh>
        </geometry>
      </visual>
      <visual name="base_link_fixed_joint_lump__M2_visual_visual_16">
        <pose>-0.1232500000000001 -0.018199999999999949 0.061316924974322257 3.944304526105059e-31 -4.4408920985006262e-16 -1.7763568394002501e-15</pose>
        <geometry>
          <mesh>
            <scale>0.001 0.001 0.001</scale>
            <uri>meshes/M2.stl</uri>
          </mesh>
        </geometry>
      </visual>
      <visual name="overhead_apriltag_20_visual">
        <pose>0 0 0.24 0 0 0</pose>
        <cast_shadows>false</cast_shadows>
        <geometry>
          <plane>
            <normal>0 0 1</normal>
            <size>0.48 0.48</size>
          </plane>
        </geometry>
        <material>
          <ambient>1 1 1 1</ambient>
          <diffuse>1 1 1 1</diffuse>
          <specular>0 0 0 1</specular>
          <pbr>
            <metal>
              <albedo_map>model://apriltag_textures/materials/textures/tag36_11_00020.png</albedo_map>
              <roughness>1.0</roughness>
            </metal>
          </pbr>
        </material>
      </visual>
      <sensor name="camera" type="camera">
        <pose relative_to="camera_link">0 0 0 0 0 0</pose>
        <always_on>true</always_on>
        <update_rate>15</update_rate>
        <visualize>false</visualize>
        <topic>/camera</topic>
        <gz:frame_id>camera_link</gz:frame_id>
        <camera>
          <horizontal_fov>1.3962634</horizontal_fov>
          <image>
            <width>640</width>
            <height>480</height>
            <format>R8G8B8</format>
          </image>
          <clip>
            <near>0.02</near>
            <far>300</far>
          </clip>
        </camera>
      </sensor>
      <sensor name="imu" type="imu">
        <pose relative_to="imu_link">0 0 0 0 0 0</pose>
        <always_on>true</always_on>
        <update_rate>100</update_rate>
        <topic>/imu/data</topic>
        <gz:frame_id>imu_link</gz:frame_id>
      </sensor>
      <sensor name="lidar" type="gpu_lidar">
        <pose relative_to="lidar_link">0 0 0 0 0 0</pose>
        <always_on>true</always_on>
        <update_rate>10</update_rate>
        <visualize>false</visualize>
        <topic>/lidar</topic>
        <gz:frame_id>base_laser</gz:frame_id>
        <lidar>
          <scan>
            <horizontal>
              <samples>360</samples>
              <resolution>1</resolution>
              <min_angle>-3.14159</min_angle>
              <max_angle>3.14159</max_angle>
            </horizontal>
            <vertical>
              <samples>1</samples>
              <resolution>1</resolution>
              <min_angle>0</min_angle>
              <max_angle>0</max_angle>
            </vertical>
          </scan>
          <range>
            <min>0.08</min>
            <max>10.0</max>
            <resolution>0.01</resolution>
          </range>
          <noise>
            <type>gaussian</type>
            <mean>0</mean>
            <stddev>0.01</stddev>
          </noise>
        </lidar>
      </sensor>
    </link>
    <link name="LTracks">
      <pose>-0.001557510734135181 0.18240000000000001 -0.0020559556759162968 0.00097071200726441095 0 -1.5707963267948972</pose>
      <inertial>
        <mass>0.1</mass>
        <inertia>
          <ixx>0.0001</ixx>
          <iyy>0.0001</iyy>
          <izz>0.0001</izz>
          <ixy>0</ixy>
          <ixz>0</ixz>
          <iyz>0</iyz>
        </inertia>
      </inertial>
      <visual name="LTracks_visual">
        <geometry>
          <mesh>
            <scale>0.001 0.001 0.001</scale>
            <uri>meshes/LTracks.stl</uri>
          </mesh>
        </geometry>
        <transparency>1.0</transparency>
      </visual>
      <collision name="LTracks_drive_proxy_collision">
        <pose>0.0912 0.01835843 -0.0114 0 0 0</pose>
        <geometry>
          <box>
            <size>0.030 0.210 0.007</size>
          </box>
        </geometry>
        <surface>
          <friction>
            <ode>
              <mu>0.7</mu>
              <mu2>150</mu2>
              <fdir1>0 1 0</fdir1>
            </ode>
          </friction>
        </surface>
      </collision>
      <visual name="LTracks_drive_proxy_visual">
        <pose>0.0912 0.01835843 -0.0114 0 0 0</pose>
        <geometry>
          <box>
            <size>0.030 0.210 0.007</size>
          </box>
        </geometry>
        <transparency>0.25</transparency>
        <material>
          <ambient>0.0 0.25 1.0 1</ambient>
          <diffuse>0.0 0.25 1.0 1</diffuse>
        </material>
      </visual>
    </link>
    <link name="RTracks">
      <pose>-0.0015575107341351949 -9.7144514654701197e-17 -0.0020559556759161858 0.00097071200726441106 1.6263032587282567e-19 -1.5707963267948979</pose>
      <inertial>
        <mass>0.1</mass>
        <inertia>
          <ixx>0.0001</ixx>
          <iyy>0.0001</iyy>
          <izz>0.0001</izz>
          <ixy>0</ixy>
          <ixz>0</ixz>
          <iyz>0</iyz>
        </inertia>
      </inertial>
      <visual name="RTracks_visual">
        <geometry>
          <mesh>
            <scale>0.001 0.001 0.001</scale>
            <uri>meshes/RTracks.stl</uri>
          </mesh>
        </geometry>
        <transparency>1.0</transparency>
      </visual>
      <collision name="RTracks_drive_proxy_collision">
        <pose>0.0912 0.01835843 -0.0114 0 0 0</pose>
        <geometry>
          <box>
            <size>0.030 0.210 0.007</size>
          </box>
        </geometry>
        <surface>
          <friction>
            <ode>
              <mu>0.7</mu>
              <mu2>150</mu2>
              <fdir1>0 1 0</fdir1>
            </ode>
          </friction>
        </surface>
      </collision>
      <visual name="RTracks_drive_proxy_visual">
        <pose>0.0912 0.01835843 -0.0114 0 0 0</pose>
        <geometry>
          <box>
            <size>0.030 0.210 0.007</size>
          </box>
        </geometry>
        <transparency>0.25</transparency>
        <material>
          <ambient>0.0 0.8 0.25 1</ambient>
          <diffuse>0.0 0.8 0.25 1</diffuse>
        </material>
      </visual>
    </link>
    <joint name="Chassis_Revolute-1" type="revolute">
      <pose relative_to="base_link">-0.0067560737940930496 -0.075700000000000003 0.068063227106018198 -1.5707963267948957 4.4408920985006262e-16 -1.570796326794897</pose>
      <parent>base_link</parent>
      <child>BRLegs</child>
      <axis>
        <xyz>-1 4.9303806576313238e-32 -1.448928193263085e-31</xyz>
        <limit>
          <lower>0</lower>
          <upper>0.261799</upper>
          <effort>1000000</effort>
          <velocity>1000000</velocity>
        </limit>
        <dynamics>
          <spring_reference>0.18</spring_reference>
          <spring_stiffness>350</spring_stiffness>
          <damping>18</damping>
        </dynamics>
      </axis>
    </joint>
    <link name="BRLegs">
      <pose relative_to="Chassis_Revolute-1">0 0 0 0 0 0</pose>
      <inertial>
        <pose>0.01549993864504774 0.037918729808493902 -0.042911399924597297 0 -2.4308653429145079e-63 0</pose>
        <mass>0.066624269603717368</mass>
        <inertia>
          <ixx>9.3209571196855136e-05</ixx>
          <ixy>8.5215220737265302e-11</ixy>
          <ixz>-9.6435329536572693e-11</ixz>
          <iyy>6.8330975762154119e-05</iyy>
          <iyz>3.911847322672697e-05</iyz>
          <izz>5.8628985513232079e-05</izz>
        </inertia>
      </inertial>
      <visual name="BRLegs_visual_visual">
        <pose>-0.075700000000000003 0.069974419999999996 0.0051492900000001639 1.570796326794897 3.944304526105059e-31 3.1415926535897918</pose>
        <geometry>
          <mesh>
            <scale>0.001 0.001 0.001</scale>
            <uri>meshes/BRLegs.stl</uri>
          </mesh>
        </geometry>
      </visual>
      <visual name="BRLegs_fixed_joint_lump__RBWheel_visual_visual_1">
        <pose>0.00050000000000000738 0.058765323033514727 -0.066502818762074395 3.1415926535897931 -1.5707963267948966 0</pose>
        <geometry>
          <mesh>
            <scale>0.001 0.001 0.001</scale>
            <uri>meshes/RBWheel.stl</uri>
          </mesh>
        </geometry>
      </visual>
    </link>
    <joint name="BRLegs_Revolute-44" type="revolute">
      <pose relative_to="BRLegs">0.015499999999999989 0.058765320000000003 -0.066502820000000004 1.570796326794897 0 -1.5707963267948957</pose>
      <parent>BRLegs</parent>
      <child>RBWheelColision</child>
      <axis>
        <xyz>3.8064789415719651e-16 -8.0491253988618555e-16 -1</xyz>
        <limit>
          <lower>-1000000</lower>
          <upper>1000000</upper>
          <effort>1000000</effort>
          <velocity>1000000</velocity>
        </limit>
      </axis>
    </joint>
    <link name="RBWheelColision">
      <pose relative_to="BRLegs_Revolute-44">0 0 0 0 0 0</pose>
      <inertial>
        <pose>-3.0335148459847972e-09 1.237925353336777e-09 -7.105427357601002e-17 -1.876739014720737e-47 0 0</pose>
        <mass>0.46240318633952909</mass>
        <inertia>
          <ixx>0.00010693073948690991</ixx>
          <ixy>-7.5604270179586037e-34</ixy>
          <ixz>9.4119178326253867e-20</ixz>
          <iyy>0.00010693073948690299</iyy>
          <iyz>2.1986451153486991e-18</iyz>
          <izz>0.00014450099573109839</izz>
        </inertia>
      </inertial>
      <visual name="RBWheelColision_visual">
        <pose>-0.011209100000000201 0.071652109999999783 0.091199999427795317 -4.4188023411456551e-16 1.5707963267948966 0</pose>
        <geometry>
          <mesh>
            <scale>0.001 0.001 0.001</scale>
            <uri>meshes/RBWheelColision.stl</uri>
          </mesh>
        </geometry>
        <material>
          <ambient>0.95 0.2 0.05 1</ambient>
          <diffuse>0.95 0.2 0.05 1</diffuse>
        </material>
      </visual>
      <collision name="RBWheelColision_collision_collision">
        <pose>-0.011209100000000201 0.071652109999999783 0.091199999427795317 -4.4188023411456551e-16 1.5707963267948966 0</pose>
        <geometry>
          <mesh>
            <scale>0.001 0.001 0.001</scale>
            <uri>meshes/RBWheelColision.stl</uri>
          </mesh>
        </geometry>
        <surface>
          <friction>
            <ode>
              <mu>1.4</mu>
              <mu2>1.4</mu2>
            </ode>
          </friction>
          <contact>
            <ode>
              <kp>500000</kp>
              <kd>50</kd>
            </ode>
          </contact>
        </surface>
      </collision>
    </link>
    <joint name="Chassis_Revolute-2" type="revolute">
      <pose relative_to="base_link">0.040250006205906942 -0.075700000000000045 0.068066927106018221 -1.5707963267948957 4.4408920985006262e-16 -1.570796326794897</pose>
      <parent>base_link</parent>
      <child>FRLegs</child>
      <axis>
        <xyz>-1 4.9303806576313238e-32 -1.448928193263085e-31</xyz>
        <limit>
          <lower>-0.261799</lower>
          <upper>0</upper>
          <effort>1000000</effort>
          <velocity>1000000</velocity>
        </limit>
        <dynamics>
          <spring_reference>-0.18</spring_reference>
          <spring_stiffness>350</spring_stiffness>
          <damping>18</damping>
        </dynamics>
      </axis>
    </joint>
    <link name="FRLegs">
      <pose relative_to="Chassis_Revolute-2">0 0 0 0 0 0</pose>
      <inertial>
        <pose>0.015499938645685369 0.037900574519914507 0.042928770370565458 0 -2.4308653429145079e-63 0</pose>
        <mass>0.066624961950021114</mass>
        <inertia>
          <ixx>9.3213353477872789e-05</ixx>
          <ixy>8.5174987417659716e-11</ixy>
          <ixz>9.6474998894865733e-11</ixz>
          <iyy>6.8367617288917984e-05</iyy>
          <iyz>-3.911601140572559e-05</iyz>
          <izz>5.8596577792667748e-05</izz>
        </inertia>
      </inertial>
      <visual name="FRLegs_visual_visual">
        <pose>-0.075700000000000045 0.069978119999999963 -0.04185678999999979 1.570796326794897 3.944304526105059e-31 3.1415926535897918</pose>
        <geometry>
          <mesh>
            <scale>0.001 0.001 0.001</scale>
            <uri>meshes/FRLegs.stl</uri>
          </mesh>
        </geometry>
      </visual>
      <visual name="FRLegs_fixed_joint_lump__RFWheel_visual_visual_1">
        <pose>0.00050000000000009585 0.058737325244174493 0.066529896391363336 -3.1415926535897931 -1.5707963267948966 0</pose>
        <geometry>
          <mesh>
            <scale>0.001 0.001 0.001</scale>
            <uri>meshes/RFWheel.stl</uri>
          </mesh>
        </geometry>
      </visual>
    </link>
    <joint name="FRLegs_Revolute-45" type="revolute">
      <pose relative_to="FRLegs">0.015499999999999989 0.058737329999999997 0.066529899999999989 1.570796326794897 0 -1.5707963267948957</pose>
      <parent>FRLegs</parent>
      <child>RFWheelColision</child>
      <axis>
        <xyz>3.8064789415719621e-16 -8.0491253988618594e-16 -1</xyz>
        <limit>
          <lower>-1000000</lower>
          <upper>1000000</upper>
          <effort>1000000</effort>
          <velocity>1000000</velocity>
        </limit>
      </axis>
    </joint>
    <link name="RFWheelColision">
      <pose relative_to="FRLegs_Revolute-45">0 0 0 0 0 0</pose>
      <inertial>
        <pose>4.7558253957191711e-09 -3.608636873764226e-09 -1.243449787580175e-16 -1.8767390147207351e-47 0 0</pose>
        <mass>0.46240318633952909</mass>
        <inertia>
          <ixx>0.00010693073948690911</ixx>
          <ixy>-1.08420217248551e-19</ixy>
          <ixz>-3.3956169066794958e-19</ixz>
          <iyy>0.0001069307394869052</iyy>
          <iyz>8.9760250836609511e-19</iyz>
          <izz>0.0001445009957311023</izz>
        </inertia>
      </inertial>
      <visual name="RFWheelColision_visual">
        <pose>-0.01120909221065996 0.071652105153437548 0.091199999427795261 -4.4188023411456502e-16 1.5707963267948966 0</pose>
        <geometry>
          <mesh>
            <scale>0.001 0.001 0.001</scale>
            <uri>meshes/RFWheelColision.stl</uri>
          </mesh>
        </geometry>
        <material>
          <ambient>0.95 0.2 0.05 1</ambient>
          <diffuse>0.95 0.2 0.05 1</diffuse>
        </material>
      </visual>
      <collision name="RFWheelColision_collision_collision">
        <pose>-0.01120909221065996 0.071652105153437548 0.091199999427795261 -4.4188023411456502e-16 1.5707963267948966 0</pose>
        <geometry>
          <mesh>
            <scale>0.001 0.001 0.001</scale>
            <uri>meshes/RFWheelColision.stl</uri>
          </mesh>
        </geometry>
        <surface>
          <friction>
            <ode>
              <mu>1.4</mu>
              <mu2>1.4</mu2>
            </ode>
          </friction>
          <contact>
            <ode>
              <kp>500000</kp>
              <kd>50</kd>
            </ode>
          </contact>
        </surface>
      </collision>
    </link>
    <joint name="Chassis_Revolute-7" type="revolute">
      <pose relative_to="base_link">0.04025000620590706 0.075699999999999878 0.068066927106018277 1.570796326794897 4.4408920985006262e-16 -1.570796326794897</pose>
      <parent>base_link</parent>
      <child>FLLegs</child>
      <axis>
        <xyz>1 4.9303806576313238e-32 -1.448928193263085e-31</xyz>
        <limit>
          <lower>0</lower>
          <upper>0.261799</upper>
          <effort>1000000</effort>
          <velocity>1000000</velocity>
        </limit>
        <dynamics>
          <spring_reference>0.18</spring_reference>
          <spring_stiffness>350</spring_stiffness>
          <damping>18</damping>
        </dynamics>
      </axis>
    </joint>
    <link name="FLLegs">
      <pose relative_to="Chassis_Revolute-7">0 0 0 0 0 0</pose>
      <inertial>
        <pose>-0.01549992722325589 -0.03790017253574187 -0.042928315055855197 0 4.004783512012162e-63 0</pose>
        <mass>0.066623676641007351</mass>
        <inertia>
          <ixx>9.3211987501414542e-05</ixx>
          <ixy>1.010321497144952e-10</ixy>
          <ixz>1.144359128873898e-10</ixz>
          <iyy>6.8366752173165701e-05</iyy>
          <iyz>-3.9115371795648407e-05</iyz>
          <izz>5.8595843364243652e-05</izz>
        </inertia>
      </inertial>
      <visual name="FLLegs_visual_visual">
        <pose>0.075700000000000003 -0.069978120000000005 0.041856789999999998 -1.5707963267948959 5.2322406978944533e-32 4.9303806576313227e-32</pose>
        <geometry>
          <mesh>
            <scale>0.001 0.001 0.001</scale>
            <uri>meshes/FLLegs.stl</uri>
          </mesh>
        </geometry>
      </visual>
      <visual name="FLLegs_fixed_joint_lump__LFWheel_visual_visual_1">
        <pose>-0.00050000000000005249 -0.058737325244174583 -0.066529896391363141 -9.1603462307061304e-16 1.5707963267948966 0</pose>
        <geometry>
          <mesh>
            <scale>0.001 0.001 0.001</scale>
            <uri>meshes/LFWheel.stl</uri>
          </mesh>
        </geometry>
      </visual>
    </link>
    <joint name="FLLegs_Revolute-42" type="revolute">
      <pose relative_to="FLLegs">-0.015499999999999989 -0.058737329999999997 -0.066529899999999989 -1.5707963267948957 0 1.570796326794897</pose>
      <parent>FLLegs</parent>
      <child>RFWheelColision-1</child>
      <axis>
        <xyz>3.8064789415719631e-16 8.0491253988618594e-16 1</xyz>
        <limit>
          <lower>-1000000</lower>
          <upper>1000000</upper>
          <effort>1000000</effort>
          <velocity>1000000</velocity>
        </limit>
      </axis>
    </joint>
    <link name="RFWheelColision-1">
      <pose relative_to="FLLegs_Revolute-42">0 0 0 0 0 0</pose>
      <inertial>
        <pose>4.755825313562667e-09 -3.608637246799163e-09 7.105427357601002e-17 0 0 0</pose>
        <mass>0.46240318633952909</mass>
        <inertia>
          <ixx>0.0001069307394869143</ixx>
          <ixy>-8.8589548433937957e-34</ixy>
          <ixz>-6.9043037319328214e-19</ixz>
          <iyy>0.0001069307394869008</iyy>
          <iyz>-8.3712096761070996e-19</iyz>
          <izz>0.00014450099573110051</izz>
        </inertia>
      </inertial>
      <visual name="RFWheelColision-1_visual">
        <pose>-0.01120909221065994 0.071652105153437132 0.091199999427795359 1.2325951644077929e-32 1.5707963267948966 0</pose>
        <geometry>
          <mesh>
            <scale>0.001 0.001 0.001</scale>
            <uri>meshes/RFWheelColision-1.stl</uri>
          </mesh>
        </geometry>
        <material>
          <ambient>0.95 0.2 0.05 1</ambient>
          <diffuse>0.95 0.2 0.05 1</diffuse>
        </material>
      </visual>
      <collision name="RFWheelColision-1_collision_collision">
        <pose>-0.01120909221065994 0.071652105153437132 0.091199999427795359 1.2325951644077929e-32 1.5707963267948966 0</pose>
        <geometry>
          <mesh>
            <scale>0.001 0.001 0.001</scale>
            <uri>meshes/RFWheelColision-1.stl</uri>
          </mesh>
        </geometry>
        <surface>
          <friction>
            <ode>
              <mu>1.4</mu>
              <mu2>1.4</mu2>
            </ode>
          </friction>
          <contact>
            <ode>
              <kp>500000</kp>
              <kd>50</kd>
            </ode>
          </contact>
        </surface>
      </collision>
    </link>
    <joint name="Chassis_Revolute-8" type="revolute">
      <pose relative_to="base_link">-0.0067560737940929247 0.075699999999999934 0.068063227106018254 1.570796326794897 4.4408920985006262e-16 -1.570796326794897</pose>
      <parent>base_link</parent>
      <child>BLLegs</child>
      <axis>
        <xyz>1 4.9303806576313238e-32 -1.448928193263085e-31</xyz>
        <limit>
          <lower>-0.261799</lower>
          <upper>0</upper>
          <effort>1000000</effort>
          <velocity>1000000</velocity>
        </limit>
        <dynamics>
          <spring_reference>-0.18</spring_reference>
          <spring_stiffness>350</spring_stiffness>
          <damping>18</damping>
        </dynamics>
      </axis>
    </joint>
    <link name="BLLegs">
      <pose relative_to="Chassis_Revolute-8">0 0 0 0 0 0</pose>
      <inertial>
        <pose>-0.01549992722249951 -0.037918327630259291 0.042910944792429448 0 4.004783512012162e-63 0</pose>
        <mass>0.066622984294703591</mass>
        <inertia>
          <ixx>9.3208205281884705e-05</ixx>
          <ixy>1.010798734819786e-10</ixy>
          <ixz>-1.143888355618992e-10</ixz>
          <iyy>6.8330111235220353e-05</iyy>
          <iyz>3.9117848619110189e-05</iyz>
          <izz>5.862825055747659e-05</izz>
        </inertia>
      </inertial>
      <visual name="BLLegs_visual_visual">
        <pose>0.075700000000000003 -0.069974420000000009 -0.0051492899999999999 -1.5707963267948959 5.2322406978944533e-32 4.9303806576313227e-32</pose>
        <geometry>
          <mesh>
            <scale>0.001 0.001 0.001</scale>
            <uri>meshes/BLLegs.stl</uri>
          </mesh>
        </geometry>
      </visual>
      <visual name="BLLegs_fixed_joint_lump__LBWheel_visual_visual_1">
        <pose>-0.00049999999999994493 -0.058765323033514782 0.06650281876207452 -9.2121338251012544e-16 1.5707963267948966 0</pose>
        <geometry>
          <mesh>
            <scale>0.001 0.001 0.001</scale>
            <uri>meshes/LBWheel.stl</uri>
          </mesh>
        </geometry>
      </visual>
    </link>
    <joint name="BLLegs_Revolute-43" type="revolute">
      <pose relative_to="BLLegs">-0.015499999999999989 -0.058765320000000003 0.066502820000000004 1.570796326794897 0 1.570796326794897</pose>
      <parent>BLLegs</parent>
      <child>LBWheelColision</child>
      <axis>
        <xyz>-3.8064789415719651e-16 8.0491253988618555e-16 1</xyz>
        <limit>
          <lower>-1000000</lower>
          <upper>1000000</upper>
          <effort>1000000</effort>
          <velocity>1000000</velocity>
        </limit>
      </axis>
    </joint>
    <link name="LBWheelColision">
      <pose relative_to="BLLegs_Revolute-43">0 0 0 0 0 0</pose>
      <inertial>
        <pose>-3.033514961447992e-09 -1.2379252023464461e-09 0 0 0 0</pose>
        <mass>0.46240318633952909</mass>
        <inertia>
          <ixx>0.000106930739486916</ixx>
          <ixy>1.084202172485503e-19</ixy>
          <ixz>-1.430103892229469e-20</ixz>
          <iyy>0.0001069307394869043</iyy>
          <iyz>4.6392163937189151e-19</iyz>
          <izz>0.00014450099573109921</izz>
        </inertia>
      </inertial>
      <visual name="LBWheelColision_visual">
        <pose>-0.01120910000000021 -0.071652109999999589 -0.091199999427795331 3.1415926535897931 -1.5707963267948966 0</pose>
        <geometry>
          <mesh>
            <scale>0.001 0.001 0.001</scale>
            <uri>meshes/LBWheelColision.stl</uri>
          </mesh>
        </geometry>
        <material>
          <ambient>0.95 0.2 0.05 1</ambient>
          <diffuse>0.95 0.2 0.05 1</diffuse>
        </material>
      </visual>
      <collision name="LBWheelColision_collision_collision">
        <pose>-0.01120910000000021 -0.071652109999999589 -0.091199999427795331 3.1415926535897931 -1.5707963267948966 0</pose>
        <geometry>
          <mesh>
            <scale>0.001 0.001 0.001</scale>
            <uri>meshes/LBWheelColision.stl</uri>
          </mesh>
        </geometry>
        <surface>
          <friction>
            <ode>
              <mu>1.4</mu>
              <mu2>1.4</mu2>
            </ode>
          </friction>
          <contact>
            <ode>
              <kp>500000</kp>
              <kd>50</kd>
            </ode>
          </contact>
        </surface>
      </collision>
    </link>
    <joint name="robotarm_z_joint" type="prismatic">
      <pose relative_to="base_link">0.066193206205906713 -0.028500000000000261 0.52188560710601828 6.8901856967953331e-16 3.80647894157197e-16 -1.570796326794897</pose>
      <parent>base_link</parent>
      <child>Leadscrew-Rigg</child>
      <axis>
        <xyz>4.9303806576313238e-32 4.9303806576313238e-32 1</xyz>
        <limit>
          <lower>0</lower>
          <upper>0.25</upper>
          <effort>1000000</effort>
          <velocity>1000000</velocity>
        </limit>
        <dynamics>
          <spring_reference>0</spring_reference>
          <spring_stiffness>0</spring_stiffness>
        </dynamics>
      </axis>
    </joint>
    <link name="Leadscrew-Rigg">
      <pose relative_to="robotarm_z_joint">0 0 0 0 0 0</pose>
      <inertial>
        <pose>-0.048686558314658727 -0.032369222112992882 -0.33682632663917272 0 0 2.4308653429145079e-63</pose>
        <mass>0.80849438330389545</mass>
        <inertia>
          <ixx>0.00084727228549970335</ixx>
          <ixy>-0.0002436430662352694</ixy>
          <ixz>0.0001397880415325847</ixz>
          <iyy>0.00068616124602953465</iyy>
          <iyz>0.00017706797130013531</iyz>
          <izz>0.00096092413880362673</izz>
        </inertia>
      </inertial>
      <visual name="Leadscrew-Rigg_visual_visual">
        <pose>-0.027999999999975121 -0.011000003078674721 -0.36000000059327369 -3.806478941571969e-16 3.637378840725568e-16 1.570796326794897</pose>
        <geometry>
          <mesh>
            <scale>0.001 0.001 0.001</scale>
            <uri>meshes/Leadscrew-Rigg.stl</uri>
          </mesh>
        </geometry>
      </visual>
      <visual name="Leadscrew-Rigg_fixed_joint_lump__Stepper-Gear-9R24.00-m2.741-1_visual_visual_1">
        <pose>-0.0279999999999751 -0.046000003078678749 -0.32900000059327378 -1.5700924586837769e-16 -1.5707963267948966 0</pose>
        <geometry>
          <mesh>
            <scale>0.001 0.001 0.001</scale>
            <uri>meshes/Stepper-Gear-9R24.00-m2.741-1.stl</uri>
          </mesh>
        </geometry>
      </visual>
      <visual name="Leadscrew-Rigg_fixed_joint_lump__Gear-9R24.00-m2.741-1-1_visual_visual_2">
        <pose>-0.027999999999975159 0.02399999692132106 -0.32900000059327378 -1.570796326794897 5.5511151231257827e-17 1.5707963267948957</pose>
        <geometry>
          <mesh>
            <scale>0.001 0.001 0.001</scale>
            <uri>meshes/Gear-9R24.00-m2.741-1-1.stl</uri>
          </mesh>
        </geometry>
      </visual>
      <visual name="Leadscrew-Rigg_fixed_joint_lump__LeadNutR_visual_visual_3">
        <pose>2.4882318427899009e-14 -3.0786747018396451e-09 -0.35250000059327369 -5.6655388976479757e-16 4.8620256398729185e-16 1.570796326794897</pose>
        <geometry>
          <mesh>
            <scale>0.001 0.001 0.001</scale>
            <uri>meshes/LeadNutR.stl</uri>
          </mesh>
        </geometry>
      </visual>
      <visual name="Leadscrew-Rigg_fixed_joint_lump__Xstepper_visual_visual_4">
        <pose>-0.069500000953675145 -0.046000003078678957 -0.32900000059327378 -3.1415926535897927 -1.5707963267948966 0</pose>
        <geometry>
          <mesh>
            <scale>0.001 0.001 0.001</scale>
            <uri>meshes/Xstepper.stl</uri>
          </mesh>
        </geometry>
      </visual>
      <visual name="Leadscrew-Rigg_fixed_joint_lump__LeadNutL_visual_visual_5">
        <pose>-0.055999999999975132 -3.0786747462485659e-09 -0.35250000059327369 -4.1852415314811016e-16 -3.2121952892376812e-17 1.570796326794897</pose>
        <geometry>
          <mesh>
            <scale>0.001 0.001 0.001</scale>
            <uri>meshes/LeadNutL.stl</uri>
          </mesh>
        </geometry>
      </visual>
    </link>
    <joint name="robotarm_x_joint" type="prismatic">
      <pose relative_to="Leadscrew-Rigg">-0.028000000000000001 -0.01100000000000001 -0.31900000000000001 -9.8607613152626476e-32 9.8607613152626476e-32 -9.7363336698435271e-32</pose>
      <parent>Leadscrew-Rigg</parent>
      <child>Gripper</child>
      <axis>
        <xyz>-6.6764900672260206e-32 1 0</xyz>
        <limit>
          <lower>0.01</lower>
          <upper>0.089999999999999997</upper>
          <effort>1000000</effort>
          <velocity>1000000</velocity>
        </limit>
        <dynamics>
          <spring_reference>0</spring_reference>
          <spring_stiffness>0</spring_stiffness>
        </dynamics>
      </axis>
    </joint>
    <link name="Gripper">
      <pose relative_to="robotarm_x_joint">0 0 0 0 0 0</pose>
      <inertial>
        <pose>-0.001335412126388815 0.13901906786714879 -0.10580022851486991 0 0 1.622964831673269e-94</pose>
        <mass>0.68361946686436115</mass>
        <inertia>
          <ixx>0.0047085707576585319</ixx>
          <ixy>4.4285922466663196e-06</ixy>
          <ixz>-5.6196714320489981e-05</ixz>
          <iyy>0.0023451903412148758</iyy>
          <iyz>0.00122175780759156</iyz>
          <izz>0.003658825347700987</izz>
        </inertia>
      </inertial>
      <visual name="Gripper_visual_visual">
        <pose>2.4390975350563338e-14 0.16707499698092601 -0.15480968205719009 -3.8064789415720198e-16 -2.2204460492503801e-16 8.6614487984360617e-16</pose>
        <geometry>
          <mesh>
            <scale>0.001 0.001 0.001</scale>
            <uri>meshes/Gripper.stl</uri>
          </mesh>
        </geometry>
      </visual>
      <visual name="Gripper_fixed_joint_lump__Servo_visual_visual_1">
        <pose>-0.0107499999999756 0.1405749969809259 -0.15480968205719009 -5.6655388976479796e-16 -3.469142038224712e-32 -1.224646799147353e-16</pose>
        <geometry>
          <mesh>
            <scale>0.001 0.001 0.001</scale>
            <uri>meshes/Servo.stl</uri>
          </mesh>
        </geometry>
      </visual>
      <visual name="Gripper_fixed_joint_lump__Servo-Gear-8L30.00-m2.1651_visual_visual_2">
        <pose>2.438500790180598e-14 0.16655699698092591 -0.15480968205719009 1.570796326794897 1.5707963267948966 0</pose>
        <geometry>
          <mesh>
            <scale>0.001 0.001 0.001</scale>
            <uri>meshes/Servo-Gear-8L30.00-m2.1651.stl</uri>
          </mesh>
        </geometry>
      </visual>
      <visual name="Gripper_fixed_joint_lump__ABX00102-Dist-sensor_visual_visual_3">
        <pose>-0.020499999999975978 0.18499999698092609 -0.14123655720970341 -1.570796326794897 0 0</pose>
        <geometry>
          <mesh>
            <scale>0.001 0.001 0.001</scale>
            <uri>meshes/ABX00102-Dist-sensor.stl</uri>
          </mesh>
        </geometry>
      </visual>
      <visual name="Gripper_fixed_joint_lump__Top-Rack-200.0mm-R30.00-m2.1651_visual_visual_4">
        <pose>0.04369498265449881 0.16707612908150279 -0.14450968205719 -3.1415926535897931 3.4450928483977351e-16 -3.1415926535897918</pose>
        <geometry>
          <mesh>
            <scale>0.001 0.001 0.001</scale>
            <uri>meshes/Top-Rack-200.0mm-R30.00-m2.1651.stl</uri>
          </mesh>
        </geometry>
      </visual>
      <visual name="Gripper_fixed_joint_lump__Bottom-Rack-200.0mm-L30.00-m2.1651_visual_visual_5">
        <pose>-0.04366271791413473 0.16707624158947121 -0.16500968205719019 3.8064789415720149e-16 3.4450928483977341e-16 -3.1415926535897918</pose>
        <geometry>
          <mesh>
            <scale>0.001 0.001 0.001</scale>
            <uri>meshes/Bottom-Rack-200.0mm-L30.00-m2.1651.stl</uri>
          </mesh>
        </geometry>
      </visual>
    </link>
    <joint name="left_gripper_finger_joint" type="revolute">
      <pose relative_to="Gripper">-0.050000000000000003 0.19514971 -0.15470967999999999 -3.1415926535897931 -5.4738221262688108e-47 -2.0088433502773088e-31</pose>
      <parent>Gripper</parent>
      <child>Finger-L-16L30.00-m2.1651</child>
      <axis>
        <xyz>4.9303806576313238e-32 4.930380657631326e-32 1.0000000000000011</xyz>
        <limit>
          <lower>-3.2288589999999999</lower>
          <upper>-0.52359900000000004</upper>
          <effort>1000000</effort>
          <velocity>1000000</velocity>
        </limit>
        <dynamics>
          <spring_reference>0</spring_reference>
          <spring_stiffness>0</spring_stiffness>
        </dynamics>
      </axis>
    </joint>
    <link name="Finger-L-16L30.00-m2.1651">
      <pose relative_to="left_gripper_finger_joint">0 0 0 0 0 0</pose>
      <inertial>
        <pose>0.0068680458231481006 -0.003114009901573987 0.001675056086278675 0 0 -2.503791303201941e-61</pose>
        <mass>0.047650149208348612</mass>
        <inertia>
          <ixx>1.452610857675738e-05</ixx>
          <ixy>6.2022278631304664e-06</ixy>
          <ixz>2.666016491166623e-06</ixz>
          <iyy>2.8583472022557919e-05</iyy>
          <iyz>-1.3311426072136151e-06</iyz>
          <izz>2.6391298869207369e-05</izz>
        </inertia>
      </inertial>
      <visual name="Finger-L-16L30.00-m2.1651_visual_visual">
        <pose>2.433608869978343e-14 -1.157878024571346e-09 0.01806250229562157 -3.1415926535897931 2.3212558142412679e-16 2.6179938779914931</pose>
        <geometry>
          <mesh>
            <scale>0.001 0.001 0.001</scale>
            <uri>meshes/Finger-L-16L30.00-m2.1651.stl</uri>
          </mesh>
        </geometry>
      </visual>
    </link>
    <joint name="right_gripper_finger_joint" type="revolute">
      <pose relative_to="Gripper">0.050000000000000003 0.19514971 -0.15470967999999999 -3.1415926535897931 -5.4738221262688108e-47 -2.0088433502773088e-31</pose>
      <parent>Gripper</parent>
      <child>Finger-R16L30.00-m2.1651Mirror</child>
      <axis>
        <xyz>4.9303806576313238e-32 4.930380657631326e-32 1.0000000000000011</xyz>
        <limit>
          <lower>0.52359900000000004</lower>
          <upper>2.96706</upper>
          <effort>1000000</effort>
          <velocity>1000000</velocity>
        </limit>
        <dynamics>
          <spring_reference>0</spring_reference>
          <spring_stiffness>0</spring_stiffness>
        </dynamics>
      </axis>
    </joint>
    <link name="Finger-R16L30.00-m2.1651Mirror">
      <pose relative_to="right_gripper_finger_joint">0 0 0 0 0 0</pose>
      <inertial>
        <pose>0.0072789473344129444 -0.0020331106970909829 -0.0016791814166278491 0 0 -2.503791303201941e-61</pose>
        <mass>0.047559344696753672</mass>
        <inertia>
          <ixx>1.421569492470173e-05</ixx>
          <ixy>5.8435646367210193e-06</ixy>
          <ixz>-2.8994167820623999e-06</ixz>
          <iyy>2.8868593743003289e-05</iyy>
          <iyz>6.9430250711753181e-07</iyz>
          <izz>2.6360063365784891e-05</izz>
        </inertia>
      </inertial>
      <visual name="Finger-R16L30.00-m2.1651Mirror_visual_visual">
        <pose>2.4451551894344449e-14 -1.157878237734167e-09 0.031937502772458583 -7.1262203928288945e-17 3.0607540456479498e-16 2.967059728390359</pose>
        <geometry>
          <mesh>
            <scale>0.001 0.001 0.001</scale>
            <uri>meshes/Finger-R16L30.00-m2.1651Mirror.stl</uri>
          </mesh>
        </geometry>
      </visual>
    </link>
    <frame name="Chassis_Revolute-11" attached_to="Chassis">
      <pose>-0.060000003794092899 0.16470000000000001 0.045250002057189938 1.570796326794897 4.4408920985006262e-16 -1.570796326794897</pose>
    </frame>
    <frame name="LDriveWheel" attached_to="Chassis_Revolute-11">
      <pose>0 0 0 0 0 0</pose>
    </frame>
    <frame name="Chassis_Revolute-12" attached_to="Chassis">
      <pose>0.21999999620590699 0.16719999999999979 0.045000002057190049 1.570796326794897 4.4408920985006262e-16 -1.570796326794897</pose>
    </frame>
    <frame name="LTWheel" attached_to="Chassis_Revolute-12">
      <pose>0 0 0 0 0 0</pose>
    </frame>
    <frame name="Chassis_Revolute-5" attached_to="Chassis">
      <pose>0.21999999620590691 0.01579999999999987 0.045000002057189993 -1.5707963267948957 4.4408920985006262e-16 -1.570796326794897</pose>
    </frame>
    <frame name="RTWheel" attached_to="Chassis_Revolute-5">
      <pose>0 0 0 0 0 0</pose>
    </frame>
    <frame name="Chassis_Revolute-6" attached_to="Chassis">
      <pose>-0.060000003794093003 0.01830000000000009 0.045250002057189889 -1.5707963267948957 4.4408920985006262e-16 -1.570796326794897</pose>
    </frame>
    <frame name="RDriveWheel" attached_to="Chassis_Revolute-6">
      <pose>0 0 0 0 0 0</pose>
    </frame>
    <frame name="Chassis_Rigid-13" attached_to="Chassis">
      <pose>-0.064079103794092984 0.043840280000000058 0.087714292057189877 3.1415926535897931 -0.095525427042366093 1.5707963267948959</pose>
    </frame>
    <frame name="Mega-wsheeld-v5-1" attached_to="Chassis_Rigid-13">
      <pose>0 0 0 0 0 0</pose>
    </frame>
    <frame name="Chassis_Rigid-14" attached_to="Chassis">
      <pose>0.078643216205906988 0.091499999999999929 0.058559682057189963 3.806478941571967e-16 3.806478941571971e-16 -1.570796326794897</pose>
    </frame>
    <frame name="ZStepper" attached_to="Chassis_Rigid-14">
      <pose>0 0 0 0 0 0</pose>
    </frame>
    <frame name="Chassis_Rigid-15" attached_to="Chassis">
      <pose>0.19199999620590699 0.13719999999999979 0.071750002057190038 3.806478941571967e-16 3.806478941571971e-16 -1.570796326794897</pose>
    </frame>
    <frame name="PI5" attached_to="Chassis_Rigid-15">
      <pose>0 0 0 0 0 0</pose>
    </frame>
    <frame name="Chassis_Rigid-16" attached_to="Chassis">
      <pose>0.23059999620590699 0.077399999999999816 0.08275000205719002 3.806478941571967e-16 3.806478941571971e-16 -1.570796326794897</pose>
    </frame>
    <frame name="LD06_LiDAR-1" attached_to="Chassis_Rigid-16">
      <pose>0 0 0 0 0 0</pose>
    </frame>
    <frame name="Chassis_Rigid-17" attached_to="Chassis">
      <pose>0.22470999620590701 0.081339999999999829 0.072750002057190011 -3.1415926535897931 3.80647894157197e-16 -1.570796326794897</pose>
    </frame>
    <frame name="BN0085" attached_to="Chassis_Rigid-17">
      <pose>0 0 0 0 0 0</pose>
    </frame>
    <frame name="Chassis_Rigid-18" attached_to="Chassis">
      <pose>0.2149999962059069 0.1018999999999998 0.06275000205719003 1.5707963267948957 -1.5707963267948966 0</pose>
    </frame>
    <frame name="rps-kamera-v2-2" attached_to="Chassis_Rigid-18">
      <pose>0 0 0 0 0 0</pose>
    </frame>
    <frame name="Chassis_Rigid-19" attached_to="Chassis">
      <pose>-0.10863002379409289 0.091500000000000109 0.006242222057189899 -1.5707963267948959 -1.9897503558217051e-16 -2.4197823938864136e-15</pose>
    </frame>
    <frame name="Unyaktig-batteri-mockup-v1-1" attached_to="Chassis_Rigid-19">
      <pose>0 0 0 0 0 0</pose>
    </frame>
    <frame name="Chassis_Rigid-20" attached_to="Chassis">
      <pose>0.12944320620590699 0.062999999999999931 -0.001440317942810023 -3.1415926535897931 3.80647894157197e-16 -1.570796326794897</pose>
    </frame>
    <frame name="RLeadscrew" attached_to="Chassis_Rigid-20">
      <pose>0 0 0 0 0 0</pose>
    </frame>
    <frame name="Leadscrew-Rigg_Revolute-26" attached_to="Leadscrew-Rigg">
      <pose>-0.028000000000000001 -0.045999999999999999 -0.32900000000000013 1.5707963267948959 2.4651903288156628e-31 -1.6412823737069559e-31</pose>
    </frame>
    <frame name="Stepper-Gear-9R24.00-m2.741-1" attached_to="Leadscrew-Rigg_Revolute-26">
      <pose>0 0 0 0 0 0</pose>
    </frame>
    <frame name="Leadscrew-Rigg_Revolute-28" attached_to="Leadscrew-Rigg">
      <pose>-0.028000000000000001 0.024 -0.32900000000000013 1.5707963267948959 2.4651903288156628e-31 -1.6412823737069559e-31</pose>
    </frame>
    <frame name="Gear-9R24.00-m2.741-1-1" attached_to="Leadscrew-Rigg_Revolute-28">
      <pose>0 0 0 0 0 0</pose>
    </frame>
    <frame name="Leadscrew-Rigg_Rigid-23" attached_to="Leadscrew-Rigg">
      <pose>0 0 -0.35249999999999998 3.1415926535897931 9.8607613152626476e-32 -3.6134346367594858e-31</pose>
    </frame>
    <frame name="LeadNutR" attached_to="Leadscrew-Rigg_Rigid-23">
      <pose>0 0 0 0 0 0</pose>
    </frame>
    <frame name="Leadscrew-Rigg_Rigid-25" attached_to="Leadscrew-Rigg">
      <pose>-0.042999999999999997 -0.045999999999999999 -0.32900000000000013 1.5707963267948959 9.8607613152626476e-32 -9.736333669843526e-32</pose>
    </frame>
    <frame name="Xstepper" attached_to="Leadscrew-Rigg_Rigid-25">
      <pose>0 0 0 0 0 0</pose>
    </frame>
    <frame name="Leadscrew-Rigg_Rigid-39" attached_to="Leadscrew-Rigg">
      <pose>-0.055999999999999987 0 -0.35249999999999998 -3.1415926535897931 -2.9605947323337481e-16 -3.689141079476218e-31</pose>
    </frame>
    <frame name="LeadNutL" attached_to="Leadscrew-Rigg_Rigid-39">
      <pose>0 0 0 0 0 0</pose>
    </frame>
    <frame name="Servo_Revolute-32" attached_to="Servo">
      <pose>-8.8817841970012525e-18 -0.01620000000000001 0.01074999999999999 1.5707963267948957 -1.5707963267948966 0</pose>
    </frame>
    <frame name="Servo-Gear-8L30.00-m2.1651" attached_to="Servo_Revolute-32">
      <pose>0 0 0 0 0 0</pose>
    </frame>
    <frame name="Gripper_Rigid-30" attached_to="Gripper">
      <pose>-0.010749999999999999 0.15057499999999999 -0.15480968000000001 3.1415926535897931 -1.5707963267948966 0</pose>
    </frame>
    <frame name="Servo" attached_to="Gripper_Rigid-30">
      <pose>0 0 0 0 0 0</pose>
    </frame>
    <frame name="Gripper_Rigid-31" attached_to="Gripper">
      <pose>0 0.185 -0.15391656000000001 -3.1415926535897931 1.5707963267948966 0</pose>
    </frame>
    <frame name="ABX00102-Dist-sensor" attached_to="Gripper_Rigid-31">
      <pose>0 0 0 0 0 0</pose>
    </frame>
    <frame name="Gripper_Slider-33" attached_to="Gripper">
      <pose>-0.065087019999999995 0.16570113 -0.13650967999999999 -3.1415926535897931 -4.9303806576313238e-32 -1.775591060142219e-32</pose>
    </frame>
    <frame name="Top-Rack-200.0mm-R30.00-m2.1651" attached_to="Gripper_Slider-33">
      <pose>0 0 0 0 0 0</pose>
    </frame>
    <frame name="Gripper_Slider-34" attached_to="Gripper">
      <pose>0.064920489999999997 0.16570124 -0.17300968 9.8607613152626476e-32 -4.9303806576313238e-32 -1.775591060142219e-32</pose>
    </frame>
    <frame name="Bottom-Rack-200.0mm-L30.00-m2.1651" attached_to="Gripper_Slider-34">
      <pose>0 0 0 0 0 0</pose>
    </frame>
    <frame name="Chassis_Rigid-21" attached_to="Chassis">
      <pose>0.12944320620590699 0.1189999999999999 -0.0014403179428100011 -3.1415926535897931 3.80647894157197e-16 -1.570796326794897</pose>
    </frame>
    <frame name="LLeadscrew" attached_to="Chassis_Rigid-21">
      <pose>0 0 0 0 0 0</pose>
    </frame>
    <frame name="Chassis_Rigid-27" attached_to="Chassis">
      <pose>0.057943206205907032 0.1249999999999999 0.056559682057189968 -3.1415926535897931 3.80647894157197e-16 -1.570796326794897</pose>
    </frame>
    <frame name="StøtteStag-1" attached_to="Chassis_Rigid-27">
      <pose>0 0 0 0 0 0</pose>
    </frame>
    <frame name="Chassis_Rigid-37" attached_to="Chassis">
      <pose>-0.060000003794092899 0.16270000000000001 0.045250002057189938 1.570796326794897 4.4408920985006262e-16 -1.570796326794897</pose>
    </frame>
    <frame name="M1" attached_to="Chassis_Rigid-37">
      <pose>0 0 0 0 0 0</pose>
    </frame>
    <frame name="Chassis_Rigid-38" attached_to="Chassis">
      <pose>-0.060000003794093003 0.020300000000000089 0.045250002057189889 -1.5707963267948957 4.4408920985006262e-16 -1.570796326794897</pose>
    </frame>
    <frame name="M2" attached_to="Chassis_Rigid-38">
      <pose>0 0 0 0 0 0</pose>
    </frame>
    <frame name="Chassis_Rigid-40" attached_to="Chassis">
      <pose>0.079995786205907055 0.1671999999999999 0.059998152057189988 3.8063627888551456e-16 -7.8746540832738967e-05 -1.570796326794897</pose>
    </frame>
    <frame name="Chassis_Rigid-41" attached_to="Chassis">
      <pose>0.07999578620590693 0.01579999999999997 0.059998152057189939 3.8064983141271268e-16 -7.8746540832927916e-05 -1.570796326794897</pose>
    </frame>
    <frame name="Chassis_to_camera_link" attached_to="Chassis">
      <pose>0.2149999962059069 0.1018999999999998 0.06275000205719003 0 0 0</pose>
    </frame>
    <frame name="camera_link" attached_to="Chassis_to_camera_link">
      <pose>0 0 0 0 0 0</pose>
    </frame>
    <frame name="Chassis_to_imu_link" attached_to="Chassis">
      <pose>0.22470999620590701 0.081339999999999829 0.072750002057190011 0 0 0</pose>
    </frame>
    <frame name="imu_link" attached_to="Chassis_to_imu_link">
      <pose>0 0 0 0 0 0</pose>
    </frame>
    <frame name="Chassis_to_lidar_link" attached_to="Chassis">
      <pose>0.23059999620590699 0.077399999999999816 0.08275000205719002 0 0 0</pose>
    </frame>
    <frame name="lidar_link" attached_to="Chassis_to_lidar_link">
      <pose>0 0 0 0 0 0</pose>
    </frame>
    <frame name="base_link_to_Chassis" attached_to="base_link">
      <pose>-0.063250000000000001 -0.091499999999999998 0.02306692504882827 0 0 0</pose>
    </frame>
    <frame name="Chassis" attached_to="base_link_to_Chassis">
      <pose>0 0 0 0 0 0</pose>
    </frame>
    <frame name="BRLegs_Revolute-3" attached_to="BRLegs">
      <pose>0.015499999999999989 0.058765320000000003 -0.066502820000000004 1.570796326794897 0 -1.5707963267948957</pose>
    </frame>
    <frame name="RBWheel" attached_to="BRLegs_Revolute-3">
      <pose>0 0 0 0 0 0</pose>
    </frame>
    <frame name="FRLegs_Revolute-4" attached_to="FRLegs">
      <pose>0.015499999999999989 0.058737329999999997 0.066529899999999989 -1.5707963267948959 -5.5511151231257827e-17 -1.5707963267948959</pose>
    </frame>
    <frame name="RFWheel" attached_to="FRLegs_Revolute-4">
      <pose>0 0 0 0 0 0</pose>
    </frame>
    <frame name="FLLegs_Revolute-9" attached_to="FLLegs">
      <pose>-0.015499999999999989 -0.058737329999999997 -0.066529899999999989 1.570796326794897 0 1.570796326794897</pose>
    </frame>
    <frame name="LFWheel" attached_to="FLLegs_Revolute-9">
      <pose>0 0 0 0 0 0</pose>
    </frame>
    <frame name="BLLegs_Revolute-10" attached_to="BLLegs">
      <pose>-0.015499999999999989 -0.058765320000000003 0.066502820000000004 1.570796326794897 0 1.570796326794897</pose>
    </frame>
    <frame name="LBWheel" attached_to="BLLegs_Revolute-10">
      <pose>0 0 0 0 0 0</pose>
    </frame>
    <joint name="base_link_to_LTracks" type="fixed">
      <parent>base_link</parent>
      <child>LTracks</child>
    </joint>
    <joint name="base_link_to_RTracks" type="fixed">
      <parent>base_link</parent>
      <child>RTracks</child>
    </joint>
    <plugin filename="gz-sim-tracked-vehicle-system" name="gz::sim::systems::TrackedVehicle">
      <left_track>
        <link>RTracks</link>
      </left_track>
      <right_track>
        <link>LTracks</link>
      </right_track>
      <tracks_separation>0.1824</tracks_separation>
      <tracks_height>0.007</tracks_height>
      <steering_efficiency>0.7</steering_efficiency>
      <topic>/model/tracked_robot/cmd_vel</topic>
      <odom_publish_frequency>50</odom_publish_frequency>
      <odom_topic>/wheel/odom</odom_topic>
      <tf_topic>tf</tf_topic>
      <frame_id>odom</frame_id>
      <child_frame_id>base_link</child_frame_id>
    </plugin>
    <plugin filename="gz-sim-track-controller-system" name="gz::sim::systems::TrackController">
      <link>LTracks</link>
      <min_velocity>-0.5555555555555556</min_velocity>
      <max_velocity>0.5555555555555556</max_velocity>
    </plugin>
    <plugin filename="gz-sim-track-controller-system" name="gz::sim::systems::TrackController">
      <link>RTracks</link>
      <min_velocity>-0.5555555555555556</min_velocity>
      <max_velocity>0.5555555555555556</max_velocity>
    </plugin>
    <plugin filename="gz-sim-joint-position-controller-system" name="gz::sim::systems::JointPositionController">
      <joint_name>robotarm_x_joint</joint_name>
      <topic>/robotarm/x_position_cmd</topic>
      <p_gain>80</p_gain>
      <i_gain>0</i_gain>
      <d_gain>20</d_gain>
      <cmd_min>0.01</cmd_min>
      <cmd_max>0.09</cmd_max>
    </plugin>
    <plugin filename="gz-sim-joint-position-controller-system" name="gz::sim::systems::JointPositionController">
      <joint_name>robotarm_z_joint</joint_name>
      <topic>/robotarm/z_position_cmd</topic>
      <p_gain>80</p_gain>
      <i_gain>10</i_gain>
      <d_gain>20</d_gain>
      <cmd_min>0.0</cmd_min>
      <cmd_max>0.25</cmd_max>
    </plugin>
    <plugin filename="gz-sim-joint-position-controller-system" name="gz::sim::systems::JointPositionController">
      <joint_name>left_gripper_finger_joint</joint_name>
      <topic>/gripper/left_position_cmd</topic>
      <p_gain>20</p_gain>
      <i_gain>0</i_gain>
      <d_gain>2</d_gain>
      <cmd_min>-3.228859</cmd_min>
      <cmd_max>-0.523599</cmd_max>
    </plugin>
    <plugin filename="gz-sim-joint-position-controller-system" name="gz::sim::systems::JointPositionController">
      <joint_name>right_gripper_finger_joint</joint_name>
      <topic>/gripper/right_position_cmd</topic>
      <p_gain>20</p_gain>
      <i_gain>0</i_gain>
      <d_gain>2</d_gain>
      <cmd_min>0.523599</cmd_min>
      <cmd_max>2.96706</cmd_max>
    </plugin>
    <plugin filename="gz-sim-joint-state-publisher-system" name="gz::sim::systems::JointStatePublisher">
      <topic>/joint_states</topic>
      <update_rate>30</update_rate>
      <joint_name>robotarm_x_joint</joint_name>
      <joint_name>robotarm_z_joint</joint_name>
      <joint_name>left_gripper_finger_joint</joint_name>
      <joint_name>right_gripper_finger_joint</joint_name>
      <joint_name>Chassis_Revolute-1</joint_name>
      <joint_name>Chassis_Revolute-2</joint_name>
      <joint_name>Chassis_Revolute-7</joint_name>
      <joint_name>Chassis_Revolute-8</joint_name>
      <joint_name>BRLegs_Revolute-44</joint_name>
      <joint_name>FRLegs_Revolute-45</joint_name>
      <joint_name>FLLegs_Revolute-42</joint_name>
      <joint_name>BLLegs_Revolute-43</joint_name>
    </plugin>
  </model>
</sdf>
